<sdf version='1.6'>
  <world name='default'>
    <light name='sun' type='directional'>
      <cast_shadows>1</cast_shadows>
      <pose frame=''>0 0 10 0 -0 0</pose>
      <diffuse>0.8 0.8 0.8 1</diffuse>
      <specular>0.2 0.2 0.2 1</specular>
      <attenuation>
        <range>1000</range>
        <constant>0.9</constant>
        <linear>0.01</linear>
        <quadratic>0.001</quadratic>
      </attenuation>
      <direction>-0.5 0.1 -0.9</direction>
    </light>
    <model name='ground_plane'>
      <static>1</static>
      <link name='link'>
        <collision name='collision'>
          <geometry>
            <plane>
              <normal>0 0 1</normal>
              <size>100 100</size>
            </plane>
          </geometry>
          <surface>
            <friction>
              <ode>
                <mu>100</mu>
                <mu2>50</mu2>
              </ode>
              <torsional>
                <ode/>
              </torsional>
            </friction>
            <contact>
              <ode/>
            </contact>
            <bounce/>
          </surface>
          <max_contacts>10</max_contacts>
        </collision>
        <visual name='visual'>
          <cast_shadows>0</cast_shadows>
          <geometry>
            <plane>
              <normal>0 0 1</normal>
              <size>100 100</size>
            </plane>
          </geometry>
          <material>
            <script>
              <uri>file://media/materials/scripts/gazebo.material</uri>
              <name>Gazebo/Grey</name>
            </script>
          </material>
        </visual>
        <self_collide>0</self_collide>
        <kinematic>0</kinematic>
      </link>
    </model>
    <gravity>0 0 -9.8</gravity>
    <magnetic_field>6e-06 2.3e-05 -4.2e-05</magnetic_field>
    <atmosphere type='adiabatic'/>
    <physics name='default_physics' default='0' type='ode'>
      <max_step_size>0.001</max_step_size>
      <real_time_factor>1</real_time_factor>
      <real_time_update_rate>1000</real_time_update_rate>
    </physics>
    <scene>
      <ambient>0.4 0.4 0.4 1</ambient>
      <background>0.7 0.7 0.7 1</background>
      <shadows>1</shadows>
    </scene>
    <spherical_coordinates>
      <surface_model>EARTH_WGS84</surface_model>
      <latitude_deg>0</latitude_deg>
      <longitude_deg>0</longitude_deg>
      <elevation>0</elevation>
      <heading_deg>0</heading_deg>
    </spherical_coordinates>
    <model name='teensize_field'>
      <static>1</static>
      <link name='field'>
        <pose frame=''>0 0 0.001 0 -0 0</pose>
        <visual name='carpet'>
          <cast_shadows>0</cast_shadows>
          <geometry>
            <plane>
              <normal>0 0 1</normal>
              <size>10.4 7.4</size>
            </plane>
          </geometry>
          <material>
            <script>
              <uri>model://teensize_field/materials/scripts/</uri>
              <uri>model://teensize_field/materials/textures/</uri>
              <name>RoboCup/Carpet</name>
            </script>
          </material>
        </visual>
        <visual name='sideline_1'>
          <pose frame=''>0 3 0.001 0 -0 0</pose>
          <cast_shadows>0</cast_shadows>
          <geometry>
            <plane>
              <normal>0 0 1</normal>
              <size>9.05 0.05</size>
            </plane>
          </geometry>
          <material>
            <script>
              <uri>file://media/materials/scripts/gazebo.material</uri>
              <name>Gazebo/White</name>
            </script>
          </material>
        </visual>
        <visual name='sideline_2'>
          <pose frame=''>0 -3 0.001 0 -0 0</pose>
          <cast_shadows>0</cast_shadows>
          <geometry>
            <plane>
              <normal>0 0 1</normal>
              <size>9.05 0.05</size>
            </plane>
          </geometry>
          <material>
            <script>
              <uri>file://media/materials/scripts/gazebo.material</uri>
              <name>Gazebo/White</name>
            </script>
          </material>
        </visual>
        <visual name='endline_1'>
          <pose frame=''>-4.5 0 0.001 0 -0 0</pose>
          <cast_shadows>0</cast_shadows>
          <geometry>
            <plane>
              <normal>0 0 1</normal>
              <size>0.05 6.05</size>
            </plane>
          </geometry>
          <material>
            <script>
              <uri>file://media/materials/scripts/gazebo.material</uri>
              <name>Gazebo/White</name>
            </script>
          </material>
        </visual>
        <visual name='endline_2'>
          <pose frame=''>4.5 0 0.001 0 -0 0</pose>
          <cast_shadows>0</cast_shadows>
          <geometry>
            <plane>
              <normal>0 0 1</normal>
              <size>0.05 6.05</size>
            </plane>
          </geometry>
          <material>
            <script>
              <uri>file://media/materials/scripts/gazebo.material</uri>
              <name>Gazebo/White</name>
            </script>
          </material>
        </visual>
        <visual name='halfway_line'>
          <pose frame=''>0 0 0.001 0 -0 0</pose>
          <cast_shadows>0</cast_shadows>
          <geometry>
            <plane>
              <normal>0 0 1</normal>
              <size>0.05 6.05</size>
            </plane>
          </geometry>
          <material>
            <script>
              <uri>file://media/materials/scripts/gazebo.material</uri>
              <name>Gazebo/White</name>
            </script>
          </material>
        </visual>
        <visual name='area_1_line_a'>
          <pose frame=''>-3.5 0 0.001 0 -0 0</pose>
          <cast_shadows>0</cast_shadows>
          <geometry>
            <plane>
              <normal>0 0 1</normal>
              <size>0.05 5.05</size>
            </plane>
          </geometry>
          <material>
            <script>
              <uri>file://media/materials/scripts/gazebo.material</uri>
              <name>Gazebo/White</name>
            </script>
          </material>
        </visual>
        <visual name='area_2_line_a'>
          <pose frame=''>-4 2.5 0.001 0 -0 0</pose>
          <cast_shadows>0</cast_shadows>
          <geometry>
            <plane>
              <normal>0 0 1</normal>
              <size>1.05 0.05</size>
            </plane>
          </geometry>
          <material>
            <script>
              <uri>file://media/materials/scripts/gazebo.material</uri>
              <name>Gazebo/White</name>
            </script>
          </material>
        </visual>
        <visual name='area_3_line_a'>
          <pose frame=''>-4 -2.5 0.001 0 -0 0</pose>
          <cast_shadows>0</cast_shadows>
          <geometry>
            <plane>
              <normal>0 0 1</normal>
              <size>1.05 0.05</size>
            </plane>
          </geometry>
          <material>
            <script>
              <uri>file://media/materials/scripts/gazebo.material</uri>
              <name>Gazebo/White</name>
            </script>
          </material>
        </visual>
        <visual name='area_1_line_b'>
          <pose frame=''>3.5 0 0.001 0 -0 0</pose>
          <cast_shadows>0</cast_shadows>
          <geometry>
            <plane>
              <normal>0 0 1</normal>
              <size>0.05 5.05</size>
            </plane>
          </geometry>
          <material>
            <script>
              <uri>file://media/materials/scripts/gazebo.material</uri>
              <name>Gazebo/White</name>
            </script>
          </material>
        </visual>
        <visual name='area_2_line_b'>
          <pose frame=''>4 2.5 0.001 0 -0 0</pose>
          <cast_shadows>0</cast_shadows>
          <geometry>
            <plane>
              <normal>0 0 1</normal>
              <size>1.05 0.05</size>
            </plane>
          </geometry>
          <material>
            <script>
              <uri>file://media/materials/scripts/gazebo.material</uri>
              <name>Gazebo/White</name>
            </script>
          </material>
        </visual>
        <visual name='area_3_line_b'>
          <pose frame=''>4 -2.5 0.001 0 -0 0</pose>
          <cast_shadows>0</cast_shadows>
          <geometry>
            <plane>
              <normal>0 0 1</normal>
              <size>1.05 0.05</size>
            </plane>
          </geometry>
          <material>
            <script>
              <uri>file://media/materials/scripts/gazebo.material</uri>
              <name>Gazebo/White</name>
            </script>
          </material>
        </visual>
        <visual name='penalty_a'>
          <pose frame=''>-2.4 0 0 0 -0 0</pose>
          <cast_shadows>0</cast_shadows>
          <geometry>
            <cylinder>
              <radius>0.05</radius>
              <length>0.0005</length>
            </cylinder>
          </geometry>
          <material>
            <script>
              <uri>file://media/materials/scripts/gazebo.material</uri>
              <name>Gazebo/White</name>
            </script>
          </material>
        </visual>
        <visual name='penalty_b'>
          <pose frame=''>2.4 0 0 0 -0 0</pose>
          <cast_shadows>0</cast_shadows>
          <geometry>
            <cylinder>
              <radius>0.05</radius>
              <length>0.0005</length>
            </cylinder>
          </geometry>
          <material>
            <script>
              <uri>file://media/materials/scripts/gazebo.material</uri>
              <name>Gazebo/White</name>
            </script>
          </material>
        </visual>
        <visual name='center_point'>
          <pose frame=''>0 0 0 0 -0 0</pose>
          <cast_shadows>0</cast_shadows>
          <geometry>
            <cylinder>
              <radius>0.05</radius>
              <length>0.0005</length>
            </cylinder>
          </geometry>
          <material>
            <script>
              <uri>file://media/materials/scripts/gazebo.material</uri>
              <name>Gazebo/White</name>
            </script>
          </material>
        </visual>
        <visual name='center_circle'>
          <pose frame=''>-0.775 -0.775 0.0005 0 -0 0</pose>
          <cast_shadows>0</cast_shadows>
          <geometry>
            <mesh>
              <uri>model://teensize_field/mesh/annulus.stl</uri>
            </mesh>
          </geometry>
          <material>
            <script>
              <uri>file://media/materials/scripts/gazebo.material</uri>
              <name>Gazebo/White</name>
            </script>
          </material>
        </visual>
        <visual name='bench'>
          <pose frame=''>0 -4 0.25 0 -0 0</pose>
          <cast_shadows>0</cast_shadows>
          <geometry>
            <box>
              <size>10.4 0.4 0.5</size>
            </box>
          </geometry>
          <material>
            <script>
              <uri>file://media/materials/scripts/gazebo.material</uri>
              <name>Gazebo/FlatBlack</name>
            </script>
          </material>
        </visual>
        <visual name='positive goal'>
          <pose frame=''>5 -4 0.5 0 -0 0</pose>
          <cast_shadows>0</cast_shadows>
          <geometry>
            <cylinder>
              <radius>0.05</radius>
              <length>0.0005</length>
            </cylinder>
          </geometry>
          <material>
            <script>
              <uri>file://media/materials/scripts/gazebo.material</uri>
              <name>Gazebo/Red</name>
            </script>
          </material>
        </visual>
        <self_collide>0</self_collide>
        <kinematic>0</kinematic>
      </link>
      <pose frame=''>-0.062812 0.051127 0 0 -0 0</pose>
    </model>
    <model name='teensize_goal'>
      <static>1</static>
      <link name='left_post'>
        <pose frame=''>0 1.35 0.95 0 -0 0</pose>
        <collision name='collision'>
          <geometry>
            <cylinder>
              <radius>0.05</radius>
              <length>1.9</length>
            </cylinder>
          </geometry>
          <max_contacts>10</max_contacts>
          <surface>
            <contact>
              <ode/>
            </contact>
            <bounce/>
            <friction>
              <torsional>
                <ode/>
              </torsional>
              <ode/>
            </friction>
          </surface>
        </collision>
        <visual name='visual'>
          <geometry>
            <cylinder>
              <radius>0.05</radius>
              <length>1.9</length>
            </cylinder>
          </geometry>
          <material>
            <script>
              <uri>file://media/materials/scripts/gazebo.material</uri>
              <name>Gazebo/White</name>
            </script>
          </material>
        </visual>
        <self_collide>0</self_collide>
        <kinematic>0</kinematic>
      </link>
      <link name='left_support_horiz_lower'>
        <pose frame=''>0.3 1.35 0.01 0 -0 0</pose>
        <collision name='collision'>
          <geometry>
            <box>
              <size>0.6 0.02 0.02</size>
            </box>
          </geometry>
          <max_contacts>10</max_contacts>
          <surface>
            <contact>
              <ode/>
            </contact>
            <bounce/>
            <friction>
              <torsional>
                <ode/>
              </torsional>
              <ode/>
            </friction>
          </surface>
        </collision>
        <visual name='visual'>
          <geometry>
            <box>
              <size>0.6 0.02 0.02</size>
            </box>
          </geometry>
          <material>
            <script>
              <uri>file://media/materials/scripts/gazebo.material</uri>
              <name>Gazebo/White</name>
            </script>
          </material>
        </visual>
        <self_collide>0</self_collide>
        <kinematic>0</kinematic>
      </link>
      <link name='left_support_horiz_upper'>
        <pose frame=''>0.3 1.35 1.2 0 -0 0</pose>
        <collision name='collision'>
          <geometry>
            <box>
              <size>0.6 0.02 0.02</size>
            </box>
          </geometry>
          <max_contacts>10</max_contacts>
          <surface>
            <contact>
              <ode/>
            </contact>
            <bounce/>
            <friction>
              <torsional>
                <ode/>
              </torsional>
              <ode/>
            </friction>
          </surface>
        </collision>
        <visual name='visual'>
          <geometry>
            <box>
              <size>0.6 0.02 0.02</size>
            </box>
          </geometry>
          <material>
            <script>
              <uri>file://media/materials/scripts/gazebo.material</uri>
              <name>Gazebo/White</name>
            </script>
          </material>
        </visual>
        <self_collide>0</self_collide>
        <kinematic>0</kinematic>
      </link>
      <link name='left_support_vertical'>
        <pose frame=''>0.6 1.35 0.6 3.14159 1.57079 3.14159</pose>
        <collision name='collision'>
          <geometry>
            <box>
              <size>1.2 0.02 0.02</size>
            </box>
          </geometry>
          <max_contacts>10</max_contacts>
          <surface>
            <contact>
              <ode/>
            </contact>
            <bounce/>
            <friction>
              <torsional>
                <ode/>
              </torsional>
              <ode/>
            </friction>
          </surface>
        </collision>
        <visual name='visual'>
          <geometry>
            <box>
              <size>1.2 0.02 0.02</size>
            </box>
          </geometry>
          <material>
            <script>
              <uri>file://media/materials/scripts/gazebo.material</uri>
              <name>Gazebo/White</name>
            </script>
          </material>
        </visual>
        <self_collide>0</self_collide>
        <kinematic>0</kinematic>
      </link>
      <link name='right_support_horiz_lower'>
        <pose frame=''>0.3 -1.35 0.01 0 -0 0</pose>
        <collision name='collision'>
          <geometry>
            <box>
              <size>0.6 0.02 0.02</size>
            </box>
          </geometry>
          <max_contacts>10</max_contacts>
          <surface>
            <contact>
              <ode/>
            </contact>
            <bounce/>
            <friction>
              <torsional>
                <ode/>
              </torsional>
              <ode/>
            </friction>
          </surface>
        </collision>
        <visual name='visual'>
          <geometry>
            <box>
              <size>0.6 0.02 0.02</size>
            </box>
          </geometry>
          <material>
            <script>
              <uri>file://media/materials/scripts/gazebo.material</uri>
              <name>Gazebo/White</name>
            </script>
          </material>
        </visual>
        <self_collide>0</self_collide>
        <kinematic>0</kinematic>
      </link>
      <link name='right_support_horiz_upper'>
        <pose frame=''>0.3 -1.35 1.2 0 -0 0</pose>
        <collision name='collision'>
          <geometry>
            <box>
              <size>0.6 0.02 0.02</size>
            </box>
          </geometry>
          <max_contacts>10</max_contacts>
          <surface>
            <contact>
              <ode/>
            </contact>
            <bounce/>
            <friction>
              <torsional>
                <ode/>
              </torsional>
              <ode/>
            </friction>
          </surface>
        </collision>
        <visual name='visual'>
          <geometry>
            <box>
              <size>0.6 0.02 0.02</size>
            </box>
          </geometry>
          <material>
            <script>
              <uri>file://media/materials/scripts/gazebo.material</uri>
              <name>Gazebo/White</name>
            </script>
          </material>
        </visual>
        <self_collide>0</self_collide>
        <kinematic>0</kinematic>
      </link>
      <link name='right_support_vertical'>
        <pose frame=''>0.6 -1.35 0.6 3.14159 1.57079 3.14159</pose>
        <collision name='collision'>
          <geometry>
            <box>
              <size>1.2 0.02 0.02</size>
            </box>
          </geometry>
          <max_contacts>10</max_contacts>
          <surface>
            <contact>
              <ode/>
            </contact>
            <bounce/>
            <friction>
              <torsional>
                <ode/>
              </torsional>
              <ode/>
            </friction>
          </surface>
        </collision>
        <visual name='visual'>
          <geometry>
            <box>
              <size>1.2 0.02 0.02</size>
            </box>
          </geometry>
          <material>
            <script>
              <uri>file://media/materials/scripts/gazebo.material</uri>
              <name>Gazebo/White</name>
            </script>
          </material>
        </visual>
        <self_collide>0</self_collide>
        <kinematic>0</kinematic>
      </link>
      <link name='center_support_horiz_lower'>
        <pose frame=''>0.6 0 0.01 3.14159 1.57079 3.14159</pose>
        <collision name='collision'>
          <geometry>
            <box>
              <size>0.02 2.7 0.02</size>
            </box>
          </geometry>
          <max_contacts>10</max_contacts>
          <surface>
            <contact>
              <ode/>
            </contact>
            <bounce/>
            <friction>
              <torsional>
                <ode/>
              </torsional>
              <ode/>
            </friction>
          </surface>
        </collision>
        <visual name='visual'>
          <geometry>
            <box>
              <size>0.02 2.7 0.02</size>
            </box>
          </geometry>
          <material>
            <script>
              <uri>file://media/materials/scripts/gazebo.material</uri>
              <name>Gazebo/White</name>
            </script>
          </material>
        </visual>
        <self_collide>0</self_collide>
        <kinematic>0</kinematic>
      </link>
      <link name='center_support_horiz_upper'>
        <pose frame=''>0.6 0 1.2 3.14159 1.57079 3.14159</pose>
        <collision name='collision'>
          <geometry>
            <box>
              <size>0.02 2.7 0.02</size>
            </box>
          </geometry>
          <max_contacts>10</max_contacts>
          <surface>
            <contact>
              <ode/>
            </contact>
            <bounce/>
            <friction>
              <torsional>
                <ode/>
              </torsional>
              <ode/>
            </friction>
          </surface>
        </collision>
        <visual name='visual'>
          <geometry>
            <box>
              <size>0.02 2.7 0.02</size>
            </box>
          </geometry>
          <material>
            <script>
              <uri>file://media/materials/scripts/gazebo.material</uri>
              <name>Gazebo/White</name>
            </script>
          </material>
        </visual>
        <self_collide>0</self_collide>
        <kinematic>0</kinematic>
      </link>
      <link name='right_post'>
        <pose frame=''>0 -1.35 0.95 0 -0 0</pose>
        <collision name='collision'>
          <geometry>
            <cylinder>
              <radius>0.05</radius>
              <length>1.9</length>
            </cylinder>
          </geometry>
          <max_contacts>10</max_contacts>
          <surface>
            <contact>
              <ode/>
            </contact>
            <bounce/>
            <friction>
              <torsional>
                <ode/>
              </torsional>
              <ode/>
            </friction>
          </surface>
        </collision>
        <visual name='visual'>
          <geometry>
            <cylinder>
              <radius>0.05</radius>
              <length>1.9</length>
            </cylinder>
          </geometry>
          <material>
            <script>
              <uri>file://media/materials/scripts/gazebo.material</uri>
              <name>Gazebo/White</name>
            </script>
          </material>
        </visual>
        <self_collide>0</self_collide>
        <kinematic>0</kinematic>
      </link>
      <link name='crossbar'>
        <pose frame=''>0 0 1.85 1.57 1.57 0</pose>
        <collision name='collision'>
          <geometry>
            <cylinder>
              <radius>0.05</radius>
              <length>2.6</length>
            </cylinder>
          </geometry>
          <max_contacts>10</max_contacts>
          <surface>
            <contact>
              <ode/>
            </contact>
            <bounce/>
            <friction>
              <torsional>
                <ode/>
              </torsional>
              <ode/>
            </friction>
          </surface>
        </collision>
        <visual name='visual'>
          <geometry>
            <cylinder>
              <radius>0.05</radius>
              <length>2.6</length>
            </cylinder>
          </geometry>
          <material>
            <script>
              <uri>file://media/materials/scripts/gazebo.material</uri>
              <name>Gazebo/White</name>
            </script>
          </material>
        </visual>
        <self_collide>0</self_collide>
        <kinematic>0</kinematic>
      </link>
      <link name='center_net'>
        <pose frame=''>0.6 0 0.6 0 -0 0</pose>
        <collision name='collision'>
          <geometry>
            <box>
              <size>0.01 2.7 1.2</size>
            </box>
          </geometry>
          <max_contacts>10</max_contacts>
          <surface>
            <contact>
              <ode/>
            </contact>
            <bounce/>
            <friction>
              <torsional>
                <ode/>
              </torsional>
              <ode/>
            </friction>
          </surface>
        </collision>
        <visual name='visual'>
          <geometry>
            <box>
              <size>0.01 2.7 1.2</size>
            </box>
          </geometry>
          <material>
            <script>
              <uri>model://teensize_goal/materials/scripts/</uri>
              <uri>model://teensize_goal/materials/textures/</uri>
              <name>RoboCup/Net</name>
            </script>
          </material>
        </visual>
        <self_collide>0</self_collide>
        <kinematic>0</kinematic>
      </link>
      <link name='left_net'>
        <pose frame=''>0.3 1.35 0.6 0 -0 0</pose>
        <collision name='collision'>
          <geometry>
            <box>
              <size>0.6 0.01 1.2</size>
            </box>
          </geometry>
          <max_contacts>10</max_contacts>
          <surface>
            <contact>
              <ode/>
            </contact>
            <bounce/>
            <friction>
              <torsional>
                <ode/>
              </torsional>
              <ode/>
            </friction>
          </surface>
        </collision>
        <visual name='visual'>
          <geometry>
            <box>
              <size>0.6 0.01 1.2</size>
            </box>
          </geometry>
          <material>
            <script>
              <uri>model://teensize_goal/materials/scripts/</uri>
              <uri>model://teensize_goal/materials/textures/</uri>
              <name>RoboCup/Net</name>
            </script>
          </material>
        </visual>
        <self_collide>0</self_collide>
        <kinematic>0</kinematic>
      </link>
      <link name='right_net'>
        <pose frame=''>0.3 -1.35 0.6 0 -0 0</pose>
        <collision name='collision'>
          <geometry>
            <box>
              <size>0.6 0.01 1.2</size>
            </box>
          </geometry>
          <max_contacts>10</max_contacts>
          <surface>
            <contact>
              <ode/>
            </contact>
            <bounce/>
            <friction>
              <torsional>
                <ode/>
              </torsional>
              <ode/>
            </friction>
          </surface>
        </collision>
        <visual name='visual'>
          <geometry>
            <box>
              <size>0.6 0.01 1.2</size>
            </box>
          </geometry>
          <material>
            <script>
              <uri>model://teensize_goal/materials/scripts/</uri>
              <uri>model://teensize_goal/materials/textures/</uri>
              <name>RoboCup/Net</name>
            </script>
          </material>
        </visual>
        <self_collide>0</self_collide>
        <kinematic>0</kinematic>
      </link>
      <pose frame=''>4.33276 0.108233 0 0 -0 0</pose>
    </model>
    <model name='teensize_goal_0'>
      <static>1</static>
      <link name='left_post'>
        <pose frame=''>0 1.35 0.95 0 -0 0</pose>
        <collision name='collision'>
          <geometry>
            <cylinder>
              <radius>0.05</radius>
              <length>1.9</length>
            </cylinder>
          </geometry>
          <max_contacts>10</max_contacts>
          <surface>
            <contact>
              <ode/>
            </contact>
            <bounce/>
            <friction>
              <torsional>
                <ode/>
              </torsional>
              <ode/>
            </friction>
          </surface>
        </collision>
        <visual name='visual'>
          <geometry>
            <cylinder>
              <radius>0.05</radius>
              <length>1.9</length>
            </cylinder>
          </geometry>
          <material>
            <script>
              <uri>file://media/materials/scripts/gazebo.material</uri>
              <name>Gazebo/White</name>
            </script>
          </material>
        </visual>
        <self_collide>0</self_collide>
        <kinematic>0</kinematic>
      </link>
      <link name='left_support_horiz_lower'>
        <pose frame=''>0.3 1.35 0.01 0 -0 0</pose>
        <collision name='collision'>
          <geometry>
            <box>
              <size>0.6 0.02 0.02</size>
            </box>
          </geometry>
          <max_contacts>10</max_contacts>
          <surface>
            <contact>
              <ode/>
            </contact>
            <bounce/>
            <friction>
              <torsional>
                <ode/>
              </torsional>
              <ode/>
            </friction>
          </surface>
        </collision>
        <visual name='visual'>
          <geometry>
            <box>
              <size>0.6 0.02 0.02</size>
            </box>
          </geometry>
          <material>
            <script>
              <uri>file://media/materials/scripts/gazebo.material</uri>
              <name>Gazebo/White</name>
            </script>
          </material>
        </visual>
        <self_collide>0</self_collide>
        <kinematic>0</kinematic>
      </link>
      <link name='left_support_horiz_upper'>
        <pose frame=''>0.3 1.35 1.2 0 -0 0</pose>
        <collision name='collision'>
          <geometry>
            <box>
              <size>0.6 0.02 0.02</size>
            </box>
          </geometry>
          <max_contacts>10</max_contacts>
          <surface>
            <contact>
              <ode/>
            </contact>
            <bounce/>
            <friction>
              <torsional>
                <ode/>
              </torsional>
              <ode/>
            </friction>
          </surface>
        </collision>
        <visual name='visual'>
          <geometry>
            <box>
              <size>0.6 0.02 0.02</size>
            </box>
          </geometry>
          <material>
            <script>
              <uri>file://media/materials/scripts/gazebo.material</uri>
              <name>Gazebo/White</name>
            </script>
          </material>
        </visual>
        <self_collide>0</self_collide>
        <kinematic>0</kinematic>
      </link>
      <link name='left_support_vertical'>
        <pose frame=''>0.6 1.35 0.6 3.14159 1.57079 3.14159</pose>
        <collision name='collision'>
          <geometry>
            <box>
              <size>1.2 0.02 0.02</size>
            </box>
          </geometry>
          <max_contacts>10</max_contacts>
          <surface>
            <contact>
              <ode/>
            </contact>
            <bounce/>
            <friction>
              <torsional>
                <ode/>
              </torsional>
              <ode/>
            </friction>
          </surface>
        </collision>
        <visual name='visual'>
          <geometry>
            <box>
              <size>1.2 0.02 0.02</size>
            </box>
          </geometry>
          <material>
            <script>
              <uri>file://media/materials/scripts/gazebo.material</uri>
              <name>Gazebo/White</name>
            </script>
          </material>
        </visual>
        <self_collide>0</self_collide>
        <kinematic>0</kinematic>
      </link>
      <link name='right_support_horiz_lower'>
        <pose frame=''>0.3 -1.35 0.01 0 -0 0</pose>
        <collision name='collision'>
          <geometry>
            <box>
              <size>0.6 0.02 0.02</size>
            </box>
          </geometry>
          <max_contacts>10</max_contacts>
          <surface>
            <contact>
              <ode/>
            </contact>
            <bounce/>
            <friction>
              <torsional>
                <ode/>
              </torsional>
              <ode/>
            </friction>
          </surface>
        </collision>
        <visual name='visual'>
          <geometry>
            <box>
              <size>0.6 0.02 0.02</size>
            </box>
          </geometry>
          <material>
            <script>
              <uri>file://media/materials/scripts/gazebo.material</uri>
              <name>Gazebo/White</name>
            </script>
          </material>
        </visual>
        <self_collide>0</self_collide>
        <kinematic>0</kinematic>
      </link>
      <link name='right_support_horiz_upper'>
        <pose frame=''>0.3 -1.35 1.2 0 -0 0</pose>
        <collision name='collision'>
          <geometry>
            <box>
              <size>0.6 0.02 0.02</size>
            </box>
          </geometry>
          <max_contacts>10</max_contacts>
          <surface>
            <contact>
              <ode/>
            </contact>
            <bounce/>
            <friction>
              <torsional>
                <ode/>
              </torsional>
              <ode/>
            </friction>
          </surface>
        </collision>
        <visual name='visual'>
          <geometry>
            <box>
              <size>0.6 0.02 0.02</size>
            </box>
          </geometry>
          <material>
            <script>
              <uri>file://media/materials/scripts/gazebo.material</uri>
              <name>Gazebo/White</name>
            </script>
          </material>
        </visual>
        <self_collide>0</self_collide>
        <kinematic>0</kinematic>
      </link>
      <link name='right_support_vertical'>
        <pose frame=''>0.6 -1.35 0.6 3.14159 1.57079 3.14159</pose>
        <collision name='collision'>
          <geometry>
            <box>
              <size>1.2 0.02 0.02</size>
            </box>
          </geometry>
          <max_contacts>10</max_contacts>
          <surface>
            <contact>
              <ode/>
            </contact>
            <bounce/>
            <friction>
              <torsional>
                <ode/>
              </torsional>
              <ode/>
            </friction>
          </surface>
        </collision>
        <visual name='visual'>
          <geometry>
            <box>
              <size>1.2 0.02 0.02</size>
            </box>
          </geometry>
          <material>
            <script>
              <uri>file://media/materials/scripts/gazebo.material</uri>
              <name>Gazebo/White</name>
            </script>
          </material>
        </visual>
        <self_collide>0</self_collide>
        <kinematic>0</kinematic>
      </link>
      <link name='center_support_horiz_lower'>
        <pose frame=''>0.6 0 0.01 3.14159 1.57079 3.14159</pose>
        <collision name='collision'>
          <geometry>
            <box>
              <size>0.02 2.7 0.02</size>
            </box>
          </geometry>
          <max_contacts>10</max_contacts>
          <surface>
            <contact>
              <ode/>
            </contact>
            <bounce/>
            <friction>
              <torsional>
                <ode/>
              </torsional>
              <ode/>
            </friction>
          </surface>
        </collision>
        <visual name='visual'>
          <geometry>
            <box>
              <size>0.02 2.7 0.02</size>
            </box>
          </geometry>
          <material>
            <script>
              <uri>file://media/materials/scripts/gazebo.material</uri>
              <name>Gazebo/White</name>
            </script>
          </material>
        </visual>
        <self_collide>0</self_collide>
        <kinematic>0</kinematic>
      </link>
      <link name='center_support_horiz_upper'>
        <pose frame=''>0.6 0 1.2 3.14159 1.57079 3.14159</pose>
        <collision name='collision'>
          <geometry>
            <box>
              <size>0.02 2.7 0.02</size>
            </box>
          </geometry>
          <max_contacts>10</max_contacts>
          <surface>
            <contact>
              <ode/>
            </contact>
            <bounce/>
            <friction>
              <torsional>
                <ode/>
              </torsional>
              <ode/>
            </friction>
          </surface>
        </collision>
        <visual name='visual'>
          <geometry>
            <box>
              <size>0.02 2.7 0.02</size>
            </box>
          </geometry>
          <material>
            <script>
              <uri>file://media/materials/scripts/gazebo.material</uri>
              <name>Gazebo/White</name>
            </script>
          </material>
        </visual>
        <self_collide>0</self_collide>
        <kinematic>0</kinematic>
      </link>
      <link name='right_post'>
        <pose frame=''>0 -1.35 0.95 0 -0 0</pose>
        <collision name='collision'>
          <geometry>
            <cylinder>
              <radius>0.05</radius>
              <length>1.9</length>
            </cylinder>
          </geometry>
          <max_contacts>10</max_contacts>
          <surface>
            <contact>
              <ode/>
            </contact>
            <bounce/>
            <friction>
              <torsional>
                <ode/>
              </torsional>
              <ode/>
            </friction>
          </surface>
        </collision>
        <visual name='visual'>
          <geometry>
            <cylinder>
              <radius>0.05</radius>
              <length>1.9</length>
            </cylinder>
          </geometry>
          <material>
            <script>
              <uri>file://media/materials/scripts/gazebo.material</uri>
              <name>Gazebo/White</name>
            </script>
          </material>
        </visual>
        <self_collide>0</self_collide>
        <kinematic>0</kinematic>
      </link>
      <link name='crossbar'>
        <pose frame=''>0 0 1.85 1.57 1.57 0</pose>
        <collision name='collision'>
          <geometry>
            <cylinder>
              <radius>0.05</radius>
              <length>2.6</length>
            </cylinder>
          </geometry>
          <max_contacts>10</max_contacts>
          <surface>
            <contact>
              <ode/>
            </contact>
            <bounce/>
            <friction>
              <torsional>
                <ode/>
              </torsional>
              <ode/>
            </friction>
          </surface>
        </collision>
        <visual name='visual'>
          <geometry>
            <cylinder>
              <radius>0.05</radius>
              <length>2.6</length>
            </cylinder>
          </geometry>
          <material>
            <script>
              <uri>file://media/materials/scripts/gazebo.material</uri>
              <name>Gazebo/White</name>
            </script>
          </material>
        </visual>
        <self_collide>0</self_collide>
        <kinematic>0</kinematic>
      </link>
      <link name='center_net'>
        <pose frame=''>0.6 0 0.6 0 -0 0</pose>
        <collision name='collision'>
          <geometry>
            <box>
              <size>0.01 2.7 1.2</size>
            </box>
          </geometry>
          <max_contacts>10</max_contacts>
          <surface>
            <contact>
              <ode/>
            </contact>
            <bounce/>
            <friction>
              <torsional>
                <ode/>
              </torsional>
              <ode/>
            </friction>
          </surface>
        </collision>
        <visual name='visual'>
          <geometry>
            <box>
              <size>0.01 2.7 1.2</size>
            </box>
          </geometry>
          <material>
            <script>
              <uri>model://teensize_goal/materials/scripts/</uri>
              <uri>model://teensize_goal/materials/textures/</uri>
              <name>RoboCup/Net</name>
            </script>
          </material>
        </visual>
        <self_collide>0</self_collide>
        <kinematic>0</kinematic>
      </link>
      <link name='left_net'>
        <pose frame=''>0.3 1.35 0.6 0 -0 0</pose>
        <collision name='collision'>
          <geometry>
            <box>
              <size>0.6 0.01 1.2</size>
            </box>
          </geometry>
          <max_contacts>10</max_contacts>
          <surface>
            <contact>
              <ode/>
            </contact>
            <bounce/>
            <friction>
              <torsional>
                <ode/>
              </torsional>
              <ode/>
            </friction>
          </surface>
        </collision>
        <visual name='visual'>
          <geometry>
            <box>
              <size>0.6 0.01 1.2</size>
            </box>
          </geometry>
          <material>
            <script>
              <uri>model://teensize_goal/materials/scripts/</uri>
              <uri>model://teensize_goal/materials/textures/</uri>
              <name>RoboCup/Net</name>
            </script>
          </material>
        </visual>
        <self_collide>0</self_collide>
        <kinematic>0</kinematic>
      </link>
      <link name='right_net'>
        <pose frame=''>0.3 -1.35 0.6 0 -0 0</pose>
        <collision name='collision'>
          <geometry>
            <box>
              <size>0.6 0.01 1.2</size>
            </box>
          </geometry>
          <max_contacts>10</max_contacts>
          <surface>
            <contact>
              <ode/>
            </contact>
            <bounce/>
            <friction>
              <torsional>
                <ode/>
              </torsional>
              <ode/>
            </friction>
          </surface>
        </collision>
        <visual name='visual'>
          <geometry>
            <box>
              <size>0.6 0.01 1.2</size>
            </box>
          </geometry>
          <material>
            <script>
              <uri>model://teensize_goal/materials/scripts/</uri>
              <uri>model://teensize_goal/materials/textures/</uri>
              <name>RoboCup/Net</name>
            </script>
          </material>
        </visual>
        <self_collide>0</self_collide>
        <kinematic>0</kinematic>
      </link>
      <pose frame=''>-1.80857 0.923642 0 0 -0 0</pose>
    </model>
    <model name='teensize_ball'>
      <pose frame=''>-0.00335 0.022841 0.08 0 -0 0</pose>
      <static>0</static>
      <link name='ball'>
        <velocity_decay>
          <linear>0</linear>
          <angular>0.0008</angular>
        </velocity_decay>
        <inertial>
          <mass>0.26</mass>
          <inertia>
            <ixx>0.00156</ixx>
            <iyy>0.00156</iyy>
            <izz>0.00156</izz>
            <ixy>0</ixy>
            <ixz>0</ixz>
            <iyz>0</iyz>
          </inertia>
        </inertial>
        <collision name='collision'>
          <geometry>
            <sphere>
              <radius>0.08</radius>
            </sphere>
          </geometry>
          <max_contacts>10</max_contacts>
          <surface>
            <contact>
              <ode/>
            </contact>
            <bounce/>
            <friction>
              <torsional>
                <ode/>
              </torsional>
              <ode/>
            </friction>
          </surface>
        </collision>
        <visual name='visual'>
          <geometry>
            <sphere>
              <radius>0.08</radius>
            </sphere>
          </geometry>
          <material>
            <script>
              <uri>model://teensize_ball/materials/scripts/</uri>
              <uri>model://teensize_ball/materials/textures/</uri>
              <name>RoboCup/Ball</name>
            </script>
          </material>
        </visual>
        <self_collide>0</self_collide>
        <kinematic>0</kinematic>
      </link>
    </model>
    <state world_name='default'>
      <sim_time>245 263000000</sim_time>
      <real_time>0 0</real_time>
      <wall_time>1542517043 648055834</wall_time>
      <iterations>0</iterations>
      <model name='alfarobi'>
        <pose frame=''>-1 0 0 0 -0 0</pose>
        <scale>1 1 1</scale>
        <link name='base_link'>
          <pose frame=''>-1 0 0 0 -0 0</pose>
          <velocity>0 0 0 0 -0 0</velocity>
          <acceleration>0 0 0 0 -0 0</acceleration>
          <wrench>0 0 0 0 -0 0</wrench>
        </link>
        <link name='head_pan_link'>
          <pose frame=''>-1 0 0.4672 0 -0 0</pose>
          <velocity>0 0 0 0 -0 0</velocity>
          <acceleration>0 0 0 0 -0 0</acceleration>
          <wrench>0 0 0 0 -0 0</wrench>
        </link>
        <link name='head_tilt_link'>
          <pose frame=''>-1 0 0.5102 0 -0 0</pose>
          <velocity>0 0 0 0 -0 0</velocity>
          <acceleration>0 0 0 0 -0 0</acceleration>
          <wrench>0 0 0 0 -0 0</wrench>
        </link>
        <link name='l_ank_pitch_link'>
          <pose frame=''>-1 0.038525 0.043 0 -0 0</pose>
          <velocity>0 0 0 0 -0 0</velocity>
          <acceleration>0 0 0 0 -0 0</acceleration>
          <wrench>0 0 0 0 -0 0</wrench>
        </link>
        <link name='l_ank_roll_link'>
          <pose frame=''>-1 0.038525 0.043 0 -0 0</pose>
          <velocity>0 0 0 0 -0 0</velocity>
          <acceleration>0 0 0 0 -0 0</acceleration>
          <wrench>0 0 0 0 -0 0</wrench>
        </link>
        <link name='l_el_link'>
          <pose frame=''>-0.979 0.09075 0.3207 0 -0 0</pose>
          <velocity>0 0 0 0 -0 0</velocity>
          <acceleration>0 0 0 0 -0 0</acceleration>
          <wrench>0 0 0 0 -0 0</wrench>
        </link>
        <link name='l_hip_pitch_link'>
          <pose frame=''>-1 0.038525 0.2766 0 -0 0</pose>
          <velocity>0 0 0 0 -0 0</velocity>
          <acceleration>0 0 0 0 -0 0</acceleration>
          <wrench>0 0 0 0 -0 0</wrench>
        </link>
        <link name='l_hip_roll_link'>
          <pose frame=''>-1 0.038525 0.2766 0 -0 0</pose>
          <velocity>0 0 0 0 -0 0</velocity>
          <acceleration>0 0 0 0 -0 0</acceleration>
          <wrench>0 0 0 0 -0 0</wrench>
        </link>
        <link name='l_hip_yaw_link'>
          <pose frame=''>-1 0.038525 0.2766 0 -0 0</pose>
          <velocity>0 0 0 0 -0 0</velocity>
          <acceleration>0 0 0 0 -0 0</acceleration>
          <wrench>0 0 0 0 -0 0</wrench>
        </link>
        <link name='l_knee_link'>
          <pose frame=''>-1 0.038525 0.1598 0 -0 0</pose>
          <velocity>0 0 0 0 -0 0</velocity>
          <acceleration>0 0 0 0 -0 0</acceleration>
          <wrench>0 0 0 0 -0 0</wrench>
        </link>
        <link name='l_sho_pitch_link'>
          <pose frame=''>-1 0.06625 0.4439 0 -0 0</pose>
          <velocity>0 0 0 0 -0 0</velocity>
          <acceleration>0 0 0 0 -0 0</acceleration>
          <wrench>0 0 0 0 -0 0</wrench>
        </link>
        <link name='l_sho_roll_link'>
          <pose frame=''>-1 0.09075 0.4279 0 -0 0</pose>
          <velocity>0 0 0 0 -0 0</velocity>
          <acceleration>0 0 0 0 -0 0</acceleration>
          <wrench>0 0 0 0 -0 0</wrench>
        </link>
        <link name='r_ank_pitch_link'>
          <pose frame=''>-1 -0.038525 0.043 0 -0 0</pose>
          <velocity>0 0 0 0 -0 0</velocity>
          <acceleration>0 0 0 0 -0 0</acceleration>
          <wrench>0 0 0 0 -0 0</wrench>
        </link>
        <link name='r_ank_roll_link'>
          <pose frame=''>-1 -0.038525 0.043 0 -0 0</pose>
          <velocity>0 0 0 0 -0 0</velocity>
          <acceleration>0 0 0 0 -0 0</acceleration>
          <wrench>0 0 0 0 -0 0</wrench>
        </link>
        <link name='r_el_link'>
          <pose frame=''>-0.979 -0.09075 0.3207 0 -0 0</pose>
          <velocity>0 0 0 0 -0 0</velocity>
          <acceleration>0 0 0 0 -0 0</acceleration>
          <wrench>0 0 0 0 -0 0</wrench>
        </link>
        <link name='r_hip_pitch_link'>
          <pose frame=''>-1 -0.038525 0.2766 0 -0 0</pose>
          <velocity>0 0 0 0 -0 0</velocity>
          <acceleration>0 0 0 0 -0 0</acceleration>
          <wrench>0 0 0 0 -0 0</wrench>
        </link>
        <link name='r_hip_roll_link'>
          <pose frame=''>-1 -0.038525 0.2766 0 -0 0</pose>
          <velocity>0 0 0 0 -0 0</velocity>
          <acceleration>0 0 0 0 -0 0</acceleration>
          <wrench>0 0 0 0 -0 0</wrench>
        </link>
        <link name='r_hip_yaw_link'>
          <pose frame=''>-1 -0.038525 0.2766 0 -0 0</pose>
          <velocity>0 0 0 0 -0 0</velocity>
          <acceleration>0 0 0 0 -0 0</acceleration>
          <wrench>0 0 0 0 -0 0</wrench>
        </link>
        <link name='r_knee_link'>
          <pose frame=''>-1 -0.038525 0.1598 0 -0 0</pose>
          <velocity>0 0 0 0 -0 0</velocity>
          <acceleration>0 0 0 0 -0 0</acceleration>
          <wrench>0 0 0 0 -0 0</wrench>
        </link>
        <link name='r_sho_pitch_link'>
          <pose frame=''>-1 -0.06625 0.4439 0 -0 0</pose>
          <velocity>0 0 0 0 -0 0</velocity>
          <acceleration>0 0 0 0 -0 0</acceleration>
          <wrench>0 0 0 0 -0 0</wrench>
        </link>
        <link name='r_sho_roll_link'>
          <pose frame=''>-1 -0.09075 0.4279 0 -0 0</pose>
          <velocity>0 0 0 0 -0 0</velocity>
          <acceleration>0 0 0 0 -0 0</acceleration>
          <wrench>0 0 0 0 -0 0</wrench>
        </link>
      </model>
      <model name='ground_plane'>
        <pose frame=''>0 0 0 0 -0 0</pose>
        <scale>1 1 1</scale>
        <link name='link'>
          <pose frame=''>0 0 0 0 -0 0</pose>
          <velocity>0 0 0 0 -0 0</velocity>
          <acceleration>0 0 0 0 -0 0</acceleration>
          <wrench>0 0 0 0 -0 0</wrench>
        </link>
      </model>
      <model name='teensize_ball'>
        <pose frame=''>0 0 0.08 0 -0 0</pose>
        <scale>1 1 1</scale>
        <link name='ball'>
          <pose frame=''>0 0 0.08 0 -0 0</pose>
          <velocity>0 0 0 0 -0 0</velocity>
          <acceleration>0 0 0 0 -0 0</acceleration>
          <wrench>0 0 0 0 -0 0</wrench>
        </link>
      </model>
      <model name='teensize_field'>
        <pose frame=''>0 0 0 0 -0 0</pose>
        <scale>1 1 1</scale>
        <link name='field'>
          <pose frame=''>0 0 0.001 0 -0 0</pose>
          <velocity>0 0 0 0 -0 0</velocity>
          <acceleration>0 0 0 0 -0 0</acceleration>
          <wrench>0 0 0 0 -0 0</wrench>
        </link>
      </model>
      <model name='teensize_goal'>
        <pose frame=''>4.5 0 0 0 -0 0</pose>
        <scale>1 1 1</scale>
        <link name='center_net'>
          <pose frame=''>5.1 0 0.6 0 -0 0</pose>
          <velocity>0 0 0 0 -0 0</velocity>
          <acceleration>0 0 0 0 -0 0</acceleration>
          <wrench>0 0 0 0 -0 0</wrench>
        </link>
        <link name='center_support_horiz_lower'>
          <pose frame=''>5.1 0 0.01 3.14159 1.57079 3.14159</pose>
          <velocity>0 0 0 0 -0 0</velocity>
          <acceleration>0 0 0 0 -0 0</acceleration>
          <wrench>0 0 0 0 -0 0</wrench>
        </link>
        <link name='center_support_horiz_upper'>
          <pose frame=''>5.1 0 1.2 3.14159 1.57079 3.14159</pose>
          <velocity>0 0 0 0 -0 0</velocity>
          <acceleration>0 0 0 0 -0 0</acceleration>
          <wrench>0 0 0 0 -0 0</wrench>
        </link>
        <link name='crossbar'>
          <pose frame=''>4.5 0 1.85 1.57 1.57 0</pose>
          <velocity>0 0 0 0 -0 0</velocity>
          <acceleration>0 0 0 0 -0 0</acceleration>
          <wrench>0 0 0 0 -0 0</wrench>
        </link>
        <link name='left_net'>
          <pose frame=''>4.8 1.35 0.6 0 -0 0</pose>
          <velocity>0 0 0 0 -0 0</velocity>
          <acceleration>0 0 0 0 -0 0</acceleration>
          <wrench>0 0 0 0 -0 0</wrench>
        </link>
        <link name='left_post'>
          <pose frame=''>4.5 1.35 0.95 0 -0 0</pose>
          <velocity>0 0 0 0 -0 0</velocity>
          <acceleration>0 0 0 0 -0 0</acceleration>
          <wrench>0 0 0 0 -0 0</wrench>
        </link>
        <link name='left_support_horiz_lower'>
          <pose frame=''>4.8 1.35 0.01 0 -0 0</pose>
          <velocity>0 0 0 0 -0 0</velocity>
          <acceleration>0 0 0 0 -0 0</acceleration>
          <wrench>0 0 0 0 -0 0</wrench>
        </link>
        <link name='left_support_horiz_upper'>
          <pose frame=''>4.8 1.35 1.2 0 -0 0</pose>
          <velocity>0 0 0 0 -0 0</velocity>
          <acceleration>0 0 0 0 -0 0</acceleration>
          <wrench>0 0 0 0 -0 0</wrench>
        </link>
        <link name='left_support_vertical'>
          <pose frame=''>5.1 1.35 0.6 3.14159 1.57079 3.14159</pose>
          <velocity>0 0 0 0 -0 0</velocity>
          <acceleration>0 0 0 0 -0 0</acceleration>
          <wrench>0 0 0 0 -0 0</wrench>
        </link>
        <link name='right_net'>
          <pose frame=''>4.8 -1.35 0.6 0 -0 0</pose>
          <velocity>0 0 0 0 -0 0</velocity>
          <acceleration>0 0 0 0 -0 0</acceleration>
          <wrench>0 0 0 0 -0 0</wrench>
        </link>
        <link name='right_post'>
          <pose frame=''>4.5 -1.35 0.95 0 -0 0</pose>
          <velocity>0 0 0 0 -0 0</velocity>
          <acceleration>0 0 0 0 -0 0</acceleration>
          <wrench>0 0 0 0 -0 0</wrench>
        </link>
        <link name='right_support_horiz_lower'>
          <pose frame=''>4.8 -1.35 0.01 0 -0 0</pose>
          <velocity>0 0 0 0 -0 0</velocity>
          <acceleration>0 0 0 0 -0 0</acceleration>
          <wrench>0 0 0 0 -0 0</wrench>
        </link>
        <link name='right_support_horiz_upper'>
          <pose frame=''>4.8 -1.35 1.2 0 -0 0</pose>
          <velocity>0 0 0 0 -0 0</velocity>
          <acceleration>0 0 0 0 -0 0</acceleration>
          <wrench>0 0 0 0 -0 0</wrench>
        </link>
        <link name='right_support_vertical'>
          <pose frame=''>5.1 -1.35 0.6 3.14159 1.57079 3.14159</pose>
          <velocity>0 0 0 0 -0 0</velocity>
          <acceleration>0 0 0 0 -0 0</acceleration>
          <wrench>0 0 0 0 -0 0</wrench>
        </link>
      </model>
      <model name='teensize_goal_0'>
        <pose frame=''>-4.5 0 0 0 -0 3.14159</pose>
        <scale>1 1 1</scale>
        <link name='center_net'>
          <pose frame=''>-5.1 2e-06 0.6 0 -0 3.14159</pose>
          <velocity>0 0 0 0 -0 0</velocity>
          <acceleration>0 0 0 0 -0 0</acceleration>
          <wrench>0 0 0 0 -0 0</wrench>
        </link>
        <link name='center_support_horiz_lower'>
          <pose frame=''>-5.1 2e-06 0.01 3.14159 1.57079 -5e-06</pose>
          <velocity>0 0 0 0 -0 0</velocity>
          <acceleration>0 0 0 0 -0 0</acceleration>
          <wrench>0 0 0 0 -0 0</wrench>
        </link>
        <link name='center_support_horiz_upper'>
          <pose frame=''>-5.1 2e-06 1.2 3.14159 1.57079 -5e-06</pose>
          <velocity>0 0 0 0 -0 0</velocity>
          <acceleration>0 0 0 0 -0 0</acceleration>
          <wrench>0 0 0 0 -0 0</wrench>
        </link>
        <link name='crossbar'>
          <pose frame=''>-4.5 0 1.85 1.57 1.57 3.14159</pose>
          <velocity>0 0 0 0 -0 0</velocity>
          <acceleration>0 0 0 0 -0 0</acceleration>
          <wrench>0 0 0 0 -0 0</wrench>
        </link>
        <link name='left_net'>
          <pose frame=''>-4.8 -1.35 0.6 0 -0 3.14159</pose>
          <velocity>0 0 0 0 -0 0</velocity>
          <acceleration>0 0 0 0 -0 0</acceleration>
          <wrench>0 0 0 0 -0 0</wrench>
        </link>
        <link name='left_post'>
          <pose frame=''>-4.5 -1.35 0.95 0 -0 3.14159</pose>
          <velocity>0 0 0 0 -0 0</velocity>
          <acceleration>0 0 0 0 -0 0</acceleration>
          <wrench>0 0 0 0 -0 0</wrench>
        </link>
        <link name='left_support_horiz_lower'>
          <pose frame=''>-4.8 -1.35 0.01 0 -0 3.14159</pose>
          <velocity>0 0 0 0 -0 0</velocity>
          <acceleration>0 0 0 0 -0 0</acceleration>
          <wrench>0 0 0 0 -0 0</wrench>
        </link>
        <link name='left_support_horiz_upper'>
          <pose frame=''>-4.8 -1.35 1.2 0 -0 3.14159</pose>
          <velocity>0 0 0 0 -0 0</velocity>
          <acceleration>0 0 0 0 -0 0</acceleration>
          <wrench>0 0 0 0 -0 0</wrench>
        </link>
        <link name='left_support_vertical'>
          <pose frame=''>-5.1 -1.35 0.6 3.14159 1.57079 -5e-06</pose>
          <velocity>0 0 0 0 -0 0</velocity>
          <acceleration>0 0 0 0 -0 0</acceleration>
          <wrench>0 0 0 0 -0 0</wrench>
        </link>
        <link name='right_net'>
          <pose frame=''>-4.8 1.35 0.6 0 -0 3.14159</pose>
          <velocity>0 0 0 0 -0 0</velocity>
          <acceleration>0 0 0 0 -0 0</acceleration>
          <wrench>0 0 0 0 -0 0</wrench>
        </link>
        <link name='right_post'>
          <pose frame=''>-4.5 1.35 0.95 0 -0 3.14159</pose>
          <velocity>0 0 0 0 -0 0</velocity>
          <acceleration>0 0 0 0 -0 0</acceleration>
          <wrench>0 0 0 0 -0 0</wrench>
        </link>
        <link name='right_support_horiz_lower'>
          <pose frame=''>-4.8 1.35 0.01 0 -0 3.14159</pose>
          <velocity>0 0 0 0 -0 0</velocity>
          <acceleration>0 0 0 0 -0 0</acceleration>
          <wrench>0 0 0 0 -0 0</wrench>
        </link>
        <link name='right_support_horiz_upper'>
          <pose frame=''>-4.8 1.35 1.2 0 -0 3.14159</pose>
          <velocity>0 0 0 0 -0 0</velocity>
          <acceleration>0 0 0 0 -0 0</acceleration>
          <wrench>0 0 0 0 -0 0</wrench>
        </link>
        <link name='right_support_vertical'>
          <pose frame=''>-5.1 1.35 0.6 3.14159 1.57079 -5e-06</pose>
          <velocity>0 0 0 0 -0 0</velocity>
          <acceleration>0 0 0 0 -0 0</acceleration>
          <wrench>0 0 0 0 -0 0</wrench>
        </link>
      </model>
      <light name='sun'>
        <pose frame=''>0 0 10 0 -0 0</pose>
      </light>
    </state>
    <gui fullscreen='0'>
      <camera name='user_camera'>
        <pose frame=''>-2.81438 1.05469 0.820451 -0 0.319643 -0.331001</pose>
        <view_controller>orbit</view_controller>
        <projection_type>perspective</projection_type>
      </camera>
    </gui>
    <model name='alfarobi'>
      <link name='base_link'>
        <pose frame=''>0 0 0 0 -0 0</pose>
        <inertial>
          <pose frame=''>-0.001966 -0.000394 0.38794 0 -0 0</pose>
          <mass>1.2756</mass>
          <inertia>
            <ixx>3.10818</ixx>
            <ixy>-0.254602</ixy>
            <ixz>2.03182</ixz>
            <iyy>6.37878</iyy>
            <iyz>0.164179</iyz>
            <izz>5.33164</izz>
          </inertia>
        </inertial>
        <collision name='base_link_fixed_joint_lump__body_link_collision'>
          <pose frame=''>0 0 0.3536 0 -0 0</pose>
          <geometry>
            <mesh>
              <scale>1 1 1</scale>
              <uri>/home/haritsahm/alfarobi_ws/src/ROBOTIS-Common/alfarobi_description/mesh/Body.stl</uri>
            </mesh>
          </geometry>
          <surface>
            <contact>
              <ode/>
            </contact>
            <friction>
              <ode>
                <mu>0.2</mu>
                <mu2>0.2</mu2>
              </ode>
              <torsional>
                <ode/>
              </torsional>
            </friction>
            <bounce/>
          </surface>
          <max_contacts>10</max_contacts>
        </collision>
        <visual name='base_link_fixed_joint_lump__body_link_visual'>
          <pose frame=''>0 0 0.3536 0 -0 0</pose>
          <geometry>
            <mesh>
              <scale>1 1 1</scale>
              <uri>/home/haritsahm/alfarobi_ws/src/ROBOTIS-Common/alfarobi_description/mesh/Body.stl</uri>
            </mesh>
          </geometry>
          <material>
            <script>
              <name>Gazebo/White</name>
              <uri>file://media/materials/scripts/gazebo.material</uri>
            </script>
          </material>
        </visual>
        <velocity_decay/>
        <self_collide>0</self_collide>
        <gravity>1</gravity>
        <gravity>1</gravity>
        <velocity_decay/>
        <gravity>1</gravity>
        <sensor name='imu_sensor' type='imu'>
          <always_on>1</always_on>
          <update_rate>100</update_rate>
          <visualize>1</visualize>
          <topic>__default_topic__</topic>
          <plugin name='imu_plugin' filename='libgazebo_ros_imu_sensor.so'>
            <topicName>alfarobi/imu</topicName>
            <bodyName>body_link</bodyName>
            <frameName>body_link</frameName>
            <updateRateHZ>30.0</updateRateHZ>
            <gaussianNoise>0.0</gaussianNoise>
            <xyzOffset>0 0 0.0903</xyzOffset>
            <rpyOffset>0 0 0</rpyOffset>
            <robotNamespace>/</robotNamespace>
          </plugin>
          <pose frame=''>0 0 0.3536 0 -0 0</pose>
        </sensor>
        <kinematic>0</kinematic>
      </link>
      <link name='head_pan_link'>
        <pose frame=''>0 0 0.4672 0 -0 0</pose>
        <inertial>
          <pose frame=''>0.001424 0.001657 -0.007128 0 -0 0</pose>
          <mass>0.0243577</mass>
          <inertia>
            <ixx>0.00514111</ixx>
            <ixy>-0.000575303</ixy>
            <ixz>-2.4729e-05</ixz>
            <iyy>0.00819157</iyy>
            <iyz>-1.92231e-05</iyz>
            <izz>0.00113798</izz>
          </inertia>
        </inertial>
        <collision name='head_pan_link_collision'>
          <pose frame=''>0 0 0 0 -0 0</pose>
          <geometry>
            <mesh>
              <scale>1 1 1</scale>
              <uri>/home/haritsahm/alfarobi_ws/src/ROBOTIS-Common/alfarobi_description/mesh/head_pan.stl</uri>
            </mesh>
          </geometry>
          <surface>
            <contact>
              <ode/>
            </contact>
            <friction>
              <ode>
                <mu>0.2</mu>
                <mu2>0.2</mu2>
              </ode>
              <torsional>
                <ode/>
              </torsional>
            </friction>
            <bounce/>
          </surface>
          <max_contacts>10</max_contacts>
        </collision>
        <visual name='head_pan_link_visual'>
          <pose frame=''>0 0 0 0 -0 0</pose>
          <geometry>
            <mesh>
              <scale>1 1 1</scale>
              <uri>/home/haritsahm/alfarobi_ws/src/ROBOTIS-Common/alfarobi_description/mesh/head_pan.stl</uri>
            </mesh>
          </geometry>
          <material>
            <script>
              <name>Gazebo/Grey</name>
              <uri>file://media/materials/scripts/gazebo.material</uri>
            </script>
          </material>
        </visual>
        <gravity>1</gravity>
        <velocity_decay/>
        <self_collide>0</self_collide>
        <gravity>1</gravity>
        <kinematic>0</kinematic>
      </link>
      <joint name='head_pan' type='revolute'>
        <child>head_pan_link</child>
        <parent>base_link</parent>
        <axis>
          <xyz>0 0 1</xyz>
          <limit>
            <lower>-2.61799</lower>
            <upper>2.61799</upper>
            <effort>2.8</effort>
            <velocity>5.65487</velocity>
          </limit>
          <dynamics>
            <spring_reference>0</spring_reference>
            <spring_stiffness>0</spring_stiffness>
          </dynamics>
          <use_parent_model_frame>1</use_parent_model_frame>
        </axis>
      </joint>
      <link name='head_tilt_link'>
        <pose frame=''>0 0 0.5102 0 -0 0</pose>
        <inertial>
          <pose frame=''>0.007667 6.4e-05 0.018565 0 -0 0</pose>
          <mass>0.158042</mass>
          <inertia>
            <ixx>0.123968</ixx>
            <ixy>7.84944e-05</ixy>
            <ixz>7.64598e-06</ixz>
            <iyy>0.117838</iyy>
            <iyz>0.00121992</iyz>
            <izz>0.15836</izz>
          </inertia>
        </inertial>
        <collision name='head_tilt_link_collision'>
          <pose frame=''>0 0 0 0 -0 0</pose>
          <geometry>
            <mesh>
              <scale>1 1 1</scale>
              <uri>/home/haritsahm/alfarobi_ws/src/ROBOTIS-Common/alfarobi_description/mesh/head_tilt.stl</uri>
            </mesh>
          </geometry>
          <surface>
            <contact>
              <ode/>
            </contact>
            <friction>
              <ode>
                <mu>0.2</mu>
                <mu2>0.2</mu2>
              </ode>
              <torsional>
                <ode/>
              </torsional>
            </friction>
            <bounce/>
          </surface>
          <max_contacts>10</max_contacts>
        </collision>
        <visual name='head_tilt_link_visual'>
          <pose frame=''>0 0 0 0 -0 0</pose>
          <geometry>
            <mesh>
              <scale>1 1 1</scale>
              <uri>/home/haritsahm/alfarobi_ws/src/ROBOTIS-Common/alfarobi_description/mesh/head_tilt.stl</uri>
            </mesh>
          </geometry>
          <material>
            <script>
              <name>Gazebo/White</name>
              <uri>file://media/materials/scripts/gazebo.material</uri>
            </script>
          </material>
        </visual>
        <velocity_decay/>
        <self_collide>0</self_collide>
        <gravity>1</gravity>
        <gravity>1</gravity>
        <velocity_decay/>
        <sensor name='camera' type='camera'>
          <camera name='__default__'>
            <horizontal_fov>1.36136</horizontal_fov>
            <save enabled="true">
              <path>/home/haritsahm/alfarobi_ws/video/</path>
            </save>
            <image>
              <width>480</width>
              <height>360</height>
              <format>R8G8B8</format>
            </image>
            <clip>
              <near>0.001</near>
              <far>200</far>
            </clip>
          </camera>
          <always_on>1</always_on>
          <update_rate>30</update_rate>
          <visualize>1</visualize>
          <plugin name='camera_controller' filename='libgazebo_ros_camera.so'>
            <alwaysOn>true</alwaysOn>
            <updateRate>30</updateRate>
            <cameraName>alfarobi/camera</cameraName>
            <imageTopicName>image_raw</imageTopicName>
            <cameraInfoTopicName>camera_info</cameraInfoTopicName>
            <frameName>cam_gazebo_link</frameName>
            <hackBaseline>0.07</hackBaseline>
            <distortionK1>0.0</distortionK1>
            <distortionK2>0.0</distortionK2>
            <distortionK3>0.0</distortionK3>
            <distortionT1>0.0</distortionT1>
            <distortionT2>0.0</distortionT2>
            <robotNamespace>/</robotNamespace>
          </plugin>
          <pose frame=''>0.011 0 0.06 0 -0 0</pose>
        </sensor>
        <kinematic>0</kinematic>
      </link>
      <joint name='head_tilt' type='revolute'>
        <child>head_tilt_link</child>
        <parent>head_pan_link</parent>
        <axis>
          <xyz>0 -1 0</xyz>
          <limit>
            <lower>-2.61799</lower>
            <upper>2.61799</upper>
            <effort>2.8</effort>
            <velocity>5.65487</velocity>
          </limit>
          <dynamics>
            <spring_reference>0</spring_reference>
            <spring_stiffness>0</spring_stiffness>
          </dynamics>
          <use_parent_model_frame>1</use_parent_model_frame>
        </axis>
      </joint>
      <link name='l_hip_yaw_link'>
        <pose frame=''>0 0.038525 0.2766 0 -0 0</pose>
        <inertial>
          <pose frame=''>0 0.001844 0.00048 0 -0 0</pose>
          <mass>0.0270692</mass>
          <inertia>
            <ixx>0.0150191</ixx>
            <ixy>0</ixy>
            <ixz>0</ixz>
            <iyy>0.0113288</iyy>
            <iyz>-0.0007335</iyz>
            <izz>0.00618255</izz>
          </inertia>
        </inertial>
        <collision name='l_hip_yaw_link_collision'>
          <pose frame=''>0 0 0 0 -0 0</pose>
          <geometry>
            <mesh>
              <scale>1 1 1</scale>
              <uri>/home/haritsahm/alfarobi_ws/src/ROBOTIS-Common/alfarobi_description/mesh/hip_yaw.stl</uri>
            </mesh>
          </geometry>
          <surface>
            <contact>
              <ode/>
            </contact>
            <friction>
              <ode>
                <mu>0.2</mu>
                <mu2>0.2</mu2>
              </ode>
              <torsional>
                <ode/>
              </torsional>
            </friction>
            <bounce/>
          </surface>
          <max_contacts>10</max_contacts>
        </collision>
        <visual name='l_hip_yaw_link_visual'>
          <pose frame=''>0 0 0 0 -0 0</pose>
          <geometry>
            <mesh>
              <scale>1 1 1</scale>
              <uri>/home/haritsahm/alfarobi_ws/src/ROBOTIS-Common/alfarobi_description/mesh/hip_yaw.stl</uri>
            </mesh>
          </geometry>
          <material>
            <script>
              <name>Gazebo/Grey</name>
              <uri>file://media/materials/scripts/gazebo.material</uri>
            </script>
          </material>
        </visual>
        <gravity>1</gravity>
        <velocity_decay/>
        <self_collide>0</self_collide>
        <kinematic>0</kinematic>
      </link>
      <joint name='l_hip_yaw' type='revolute'>
        <child>l_hip_yaw_link</child>
        <parent>base_link</parent>
        <axis>
          <xyz>0 0 -1</xyz>
          <limit>
            <lower>-2.61799</lower>
            <upper>2.61799</upper>
            <effort>2.8</effort>
            <velocity>5.65487</velocity>
          </limit>
          <dynamics>
            <spring_reference>0</spring_reference>
            <spring_stiffness>0</spring_stiffness>
          </dynamics>
          <use_parent_model_frame>1</use_parent_model_frame>
        </axis>
      </joint>
      <link name='l_hip_roll_link'>
        <pose frame=''>0 0.038525 0.2766 0 -0 0</pose>
        <inertial>
          <pose frame=''>-0.018242 8e-05 -0.013873 0 -0 0</pose>
          <mass>0.167108</mass>
          <inertia>
            <ixx>0.122597</ixx>
            <ixy>0.000711275</ixy>
            <ixz>0.000811439</ixz>
            <iyy>0.110666</iyy>
            <iyz>-0.00716355</iyz>
            <izz>0.0418777</izz>
          </inertia>
        </inertial>
        <collision name='l_hip_roll_link_collision'>
          <pose frame=''>0 0 0 0 -0 0</pose>
          <geometry>
            <mesh>
              <scale>1 1 1</scale>
              <uri>/home/haritsahm/alfarobi_ws/src/ROBOTIS-Common/alfarobi_description/mesh/l_hip_roll.stl</uri>
            </mesh>
          </geometry>
          <surface>
            <contact>
              <ode/>
            </contact>
            <friction>
              <ode>
                <mu>0.2</mu>
                <mu2>0.2</mu2>
              </ode>
              <torsional>
                <ode/>
              </torsional>
            </friction>
            <bounce/>
          </surface>
          <max_contacts>10</max_contacts>
        </collision>
        <visual name='l_hip_roll_link_visual'>
          <pose frame=''>0 0 0 0 -0 0</pose>
          <geometry>
            <mesh>
              <scale>1 1 1</scale>
              <uri>/home/haritsahm/alfarobi_ws/src/ROBOTIS-Common/alfarobi_description/mesh/l_hip_roll.stl</uri>
            </mesh>
          </geometry>
          <material>
            <script>
              <name>Gazebo/Grey</name>
              <uri>file://media/materials/scripts/gazebo.material</uri>
            </script>
          </material>
        </visual>
        <gravity>1</gravity>
        <velocity_decay/>
        <self_collide>0</self_collide>
        <gravity>1</gravity>
        <kinematic>0</kinematic>
      </link>
      <joint name='l_hip_roll' type='revolute'>
        <child>l_hip_roll_link</child>
        <parent>l_hip_yaw_link</parent>
        <axis>
          <xyz>-1 0 0</xyz>
          <limit>
            <lower>-2.61799</lower>
            <upper>2.61799</upper>
            <effort>2.8</effort>
            <velocity>5.65487</velocity>
          </limit>
          <dynamics>
            <spring_reference>0</spring_reference>
            <spring_stiffness>0</spring_stiffness>
          </dynamics>
          <use_parent_model_frame>1</use_parent_model_frame>
        </axis>
      </joint>
      <link name='l_hip_pitch_link'>
        <pose frame=''>0 0.038525 0.2766 0 -0 0</pose>
        <inertial>
          <pose frame=''>0.000692 -0.000323 -0.092966 0 -0 0</pose>
          <mass>0.119043</mass>
          <inertia>
            <ixx>0.0979503</ixx>
            <ixy>0.00121194</ixy>
            <ixz>-0.00021223</ixz>
            <iyy>0.0328483</iyy>
            <iyz>-0.0019474</iyz>
            <izz>0.114935</izz>
          </inertia>
        </inertial>
        <collision name='l_hip_pitch_link_collision'>
          <pose frame=''>0 0 0 0 -0 0</pose>
          <geometry>
            <mesh>
              <scale>1 1 1</scale>
              <uri>/home/haritsahm/alfarobi_ws/src/ROBOTIS-Common/alfarobi_description/mesh/l_hip_pitch.stl</uri>
            </mesh>
          </geometry>
          <surface>
            <contact>
              <ode/>
            </contact>
            <friction>
              <ode>
                <mu>0.2</mu>
                <mu2>0.2</mu2>
              </ode>
              <torsional>
                <ode/>
              </torsional>
            </friction>
            <bounce/>
          </surface>
          <max_contacts>10</max_contacts>
        </collision>
        <visual name='l_hip_pitch_link_visual'>
          <pose frame=''>0 0 0 0 -0 0</pose>
          <geometry>
            <mesh>
              <scale>1 1 1</scale>
              <uri>/home/haritsahm/alfarobi_ws/src/ROBOTIS-Common/alfarobi_description/mesh/l_hip_pitch.stl</uri>
            </mesh>
          </geometry>
          <material>
            <script>
              <name>Gazebo/White</name>
              <uri>file://media/materials/scripts/gazebo.material</uri>
            </script>
          </material>
        </visual>
        <gravity>1</gravity>
        <velocity_decay/>
        <self_collide>0</self_collide>
        <gravity>1</gravity>
        <kinematic>0</kinematic>
      </link>
      <joint name='l_hip_pitch' type='revolute'>
        <child>l_hip_pitch_link</child>
        <parent>l_hip_roll_link</parent>
        <axis>
          <xyz>0 -1 0</xyz>
          <limit>
            <lower>-2.61799</lower>
            <upper>2.61799</upper>
            <effort>2.8</effort>
            <velocity>5.65487</velocity>
          </limit>
          <dynamics>
            <spring_reference>0</spring_reference>
            <spring_stiffness>0</spring_stiffness>
          </dynamics>
          <use_parent_model_frame>1</use_parent_model_frame>
        </axis>
      </joint>
      <link name='l_knee_link'>
        <pose frame=''>0 0.038525 0.1598 0 -0 0</pose>
        <inertial>
          <pose frame=''>0.006548 -0.000592 -0.053955 0 -0 0</pose>
          <mass>0.0703098</mass>
          <inertia>
            <ixx>0.0933696</ixx>
            <ixy>-0.000935674</ixy>
            <ixz>-0.000239921</ixz>
            <iyy>0.0462955</iyy>
            <iyz>-0.0128585</iyz>
            <izz>0.113515</izz>
          </inertia>
        </inertial>
        <collision name='l_knee_link_collision'>
          <pose frame=''>0 0 0 0 -0 0</pose>
          <geometry>
            <mesh>
              <scale>1 1 1</scale>
              <uri>/home/haritsahm/alfarobi_ws/src/ROBOTIS-Common/alfarobi_description/mesh/lower_leg.stl</uri>
            </mesh>
          </geometry>
          <surface>
            <contact>
              <ode/>
            </contact>
            <friction>
              <ode>
                <mu>0.2</mu>
                <mu2>0.2</mu2>
              </ode>
              <torsional>
                <ode/>
              </torsional>
            </friction>
            <bounce/>
          </surface>
          <max_contacts>10</max_contacts>
        </collision>
        <visual name='l_knee_link_visual'>
          <pose frame=''>0 0 0 0 -0 0</pose>
          <geometry>
            <mesh>
              <scale>1 1 1</scale>
              <uri>/home/haritsahm/alfarobi_ws/src/ROBOTIS-Common/alfarobi_description/mesh/lower_leg.stl</uri>
            </mesh>
          </geometry>
          <material>
            <script>
              <name>Gazebo/White</name>
              <uri>file://media/materials/scripts/gazebo.material</uri>
            </script>
          </material>
        </visual>
        <gravity>1</gravity>
        <velocity_decay/>
        <self_collide>0</self_collide>
        <gravity>1</gravity>
        <kinematic>0</kinematic>
      </link>
      <joint name='l_knee' type='revolute'>
        <child>l_knee_link</child>
        <parent>l_hip_pitch_link</parent>
        <axis>
          <xyz>0 -1 0</xyz>
          <limit>
            <lower>-2.61799</lower>
            <upper>2.61799</upper>
            <effort>2.8</effort>
            <velocity>5.65487</velocity>
          </limit>
          <dynamics>
            <spring_reference>0</spring_reference>
            <spring_stiffness>0</spring_stiffness>
          </dynamics>
          <use_parent_model_frame>1</use_parent_model_frame>
        </axis>
      </joint>
      <link name='l_ank_pitch_link'>
        <pose frame=''>0 0.038525 0.043 0 -0 0</pose>
        <inertial>
          <pose frame=''>-0.018536 -0.000214 0.013873 0 -0 0</pose>
          <mass>0.167108</mass>
          <inertia>
            <ixx>0.120792</ixx>
            <ixy>-0.000797811</ixy>
            <ixz>-0.000393222</ixz>
            <iyy>0.108855</iyy>
            <iyz>0.00707701</iyz>
            <izz>0.0418711</izz>
          </inertia>
        </inertial>
        <collision name='l_ank_pitch_link_collision'>
          <pose frame=''>0 0 0 0 -0 0</pose>
          <geometry>
            <mesh>
              <scale>1 1 1</scale>
              <uri>/home/haritsahm/alfarobi_ws/src/ROBOTIS-Common/alfarobi_description/mesh/l_ank_pitch.stl</uri>
            </mesh>
          </geometry>
          <surface>
            <contact>
              <ode/>
            </contact>
            <friction>
              <ode>
                <mu>0.2</mu>
                <mu2>0.2</mu2>
              </ode>
              <torsional>
                <ode/>
              </torsional>
            </friction>
            <bounce/>
          </surface>
          <max_contacts>10</max_contacts>
        </collision>
        <visual name='l_ank_pitch_link_visual'>
          <pose frame=''>0 0 0 0 -0 0</pose>
          <geometry>
            <mesh>
              <scale>1 1 1</scale>
              <uri>/home/haritsahm/alfarobi_ws/src/ROBOTIS-Common/alfarobi_description/mesh/l_ank_pitch.stl</uri>
            </mesh>
          </geometry>
          <material>
            <script>
              <name>Gazebo/Grey</name>
              <uri>file://media/materials/scripts/gazebo.material</uri>
            </script>
          </material>
        </visual>
        <gravity>1</gravity>
        <velocity_decay/>
        <self_collide>0</self_collide>
        <gravity>1</gravity>
        <kinematic>0</kinematic>
      </link>
      <joint name='l_ank_pitch' type='revolute'>
        <child>l_ank_pitch_link</child>
        <parent>l_knee_link</parent>
        <axis>
          <xyz>0 1 0</xyz>
          <limit>
            <lower>-2.61799</lower>
            <upper>2.61799</upper>
            <effort>2.8</effort>
            <velocity>5.65487</velocity>
          </limit>
          <dynamics>
            <spring_reference>0</spring_reference>
            <spring_stiffness>0</spring_stiffness>
          </dynamics>
          <use_parent_model_frame>1</use_parent_model_frame>
        </axis>
      </joint>
      <link name='l_ank_roll_link'>
        <pose frame=''>0 0.038525 0.043 0 -0 0</pose>
        <inertial>
          <pose frame=''>-0.000503 0.009506 -0.025995 0 -0 0</pose>
          <mass>0.0794462</mass>
          <inertia>
            <ixx>0.0683256</ixx>
            <ixy>0.00253305</ixy>
            <ixz>0.000218696</ixz>
            <iyy>0.0878905</iyy>
            <iyz>0.000976205</iyz>
            <izz>0.0358408</izz>
          </inertia>
        </inertial>
        <collision name='l_ank_roll_link_collision'>
          <pose frame=''>0 0 0 0 -0 0</pose>
          <geometry>
            <mesh>
              <scale>1 1 1</scale>
              <uri>/home/haritsahm/alfarobi_ws/src/ROBOTIS-Common/alfarobi_description/mesh/leg_ank_roll_l.stl</uri>
            </mesh>
          </geometry>
          <surface>
            <contact>
              <ode>
                <kp>100000</kp>
                <kd>100</kd>
                <max_vel>1</max_vel>
                <min_depth>0.001</min_depth>
              </ode>
            </contact>
            <friction>
              <ode>
                <mu>1.5</mu>
                <mu2>1.5</mu2>
                <fdir1>1 0 0</fdir1>
              </ode>
              <torsional>
                <ode/>
              </torsional>
            </friction>
            <bounce/>
          </surface>
          <max_contacts>10</max_contacts>
        </collision>
        <visual name='l_ank_roll_link_visual'>
          <pose frame=''>0 0 0 0 -0 0</pose>
          <geometry>
            <mesh>
              <scale>1 1 1</scale>
              <uri>/home/haritsahm/alfarobi_ws/src/ROBOTIS-Common/alfarobi_description/mesh/leg_ank_roll_l.stl</uri>
            </mesh>
          </geometry>
          <material>
            <script>
              <name>Gazebo/White</name>
              <uri>file://media/materials/scripts/gazebo.material</uri>
            </script>
          </material>
        </visual>
        <gravity>1</gravity>
        <velocity_decay/>
        <self_collide>0</self_collide>
        <gravity>1</gravity>
        <kinematic>0</kinematic>
      </link>
      <joint name='l_ank_roll' type='revolute'>
        <child>l_ank_roll_link</child>
        <parent>l_ank_pitch_link</parent>
        <axis>
          <xyz>1 0 0</xyz>
          <limit>
            <lower>-2.61799</lower>
            <upper>2.61799</upper>
            <effort>2.8</effort>
            <velocity>5.65487</velocity>
          </limit>
          <dynamics>
            <spring_reference>0</spring_reference>
            <spring_stiffness>0</spring_stiffness>
          </dynamics>
          <use_parent_model_frame>1</use_parent_model_frame>
        </axis>
      </joint>
      <link name='l_sho_pitch_link'>
        <pose frame=''>0 0.06625 0.4439 0 -0 0</pose>
        <inertial>
          <pose frame=''>0.001352 0.010264 0.001394 0 -0 0</pose>
          <mass>0.025913</mass>
          <inertia>
            <ixx>0.00977582</ixx>
            <ixy>0.00169118</ixy>
            <ixz>-0.000451743</ixz>
            <iyy>0.0105111</iyy>
            <iyz>0.00033407</iyz>
            <izz>0.0054768</izz>
          </inertia>
        </inertial>
        <collision name='l_sho_pitch_link_collision'>
          <pose frame=''>0 0 0 0 -0 0</pose>
          <geometry>
            <mesh>
              <scale>1 1 1</scale>
              <uri>/home/haritsahm/alfarobi_ws/src/ROBOTIS-Common/alfarobi_description/mesh/l_shoulder_pitch.stl</uri>
            </mesh>
          </geometry>
          <surface>
            <contact>
              <ode/>
            </contact>
            <friction>
              <ode>
                <mu>0.2</mu>
                <mu2>0.2</mu2>
              </ode>
              <torsional>
                <ode/>
              </torsional>
            </friction>
            <bounce/>
          </surface>
          <max_contacts>10</max_contacts>
        </collision>
        <visual name='l_sho_pitch_link_visual'>
          <pose frame=''>0 0 0 0 -0 0</pose>
          <geometry>
            <mesh>
              <scale>1 1 1</scale>
              <uri>/home/haritsahm/alfarobi_ws/src/ROBOTIS-Common/alfarobi_description/mesh/l_shoulder_pitch.stl</uri>
            </mesh>
          </geometry>
          <material>
            <script>
              <name>Gazebo/Grey</name>
              <uri>file://media/materials/scripts/gazebo.material</uri>
            </script>
          </material>
        </visual>
        <gravity>1</gravity>
        <velocity_decay/>
        <self_collide>0</self_collide>
        <gravity>1</gravity>
        <kinematic>0</kinematic>
      </link>
      <joint name='l_sho_pitch' type='revolute'>
        <child>l_sho_pitch_link</child>
        <parent>base_link</parent>
        <axis>
          <xyz>0 1 0</xyz>
          <limit>
            <lower>-2.61799</lower>
            <upper>2.61799</upper>
            <effort>2.8</effort>
            <velocity>5.65487</velocity>
          </limit>
          <dynamics>
            <spring_reference>0</spring_reference>
            <spring_stiffness>0</spring_stiffness>
          </dynamics>
          <use_parent_model_frame>1</use_parent_model_frame>
        </axis>
      </joint>
      <link name='l_sho_roll_link'>
        <pose frame=''>0 0.09075 0.4279 0 -0 0</pose>
        <inertial>
          <pose frame=''>0.000734 0.00066 -0.046239 0 -0 0</pose>
          <mass>0.168377</mass>
          <inertia>
            <ixx>0.122028</ixx>
            <ixy>-0.00208126</ixy>
            <ixz>-0.000881434</ixz>
            <iyy>0.0380884</iyy>
            <iyz>0.00182514</iyz>
            <izz>0.113408</izz>
          </inertia>
        </inertial>
        <collision name='l_sho_roll_link_collision'>
          <pose frame=''>0 0 0 0 -0 0</pose>
          <geometry>
            <mesh>
              <scale>1 1 1</scale>
              <uri>/home/haritsahm/alfarobi_ws/src/ROBOTIS-Common/alfarobi_description/mesh/l_shoulder_roll.stl</uri>
            </mesh>
          </geometry>
          <surface>
            <contact>
              <ode/>
            </contact>
            <friction>
              <ode>
                <mu>0.2</mu>
                <mu2>0.2</mu2>
              </ode>
              <torsional>
                <ode/>
              </torsional>
            </friction>
            <bounce/>
          </surface>
          <max_contacts>10</max_contacts>
        </collision>
        <visual name='l_sho_roll_link_visual'>
          <pose frame=''>0 0 0 0 -0 0</pose>
          <geometry>
            <mesh>
              <scale>1 1 1</scale>
              <uri>/home/haritsahm/alfarobi_ws/src/ROBOTIS-Common/alfarobi_description/mesh/l_shoulder_roll.stl</uri>
            </mesh>
          </geometry>
          <material>
            <script>
              <name>Gazebo/White</name>
              <uri>file://media/materials/scripts/gazebo.material</uri>
            </script>
          </material>
        </visual>
        <gravity>1</gravity>
        <velocity_decay/>
        <self_collide>0</self_collide>
        <gravity>1</gravity>
        <kinematic>0</kinematic>
      </link>
      <joint name='l_sho_roll' type='revolute'>
        <child>l_sho_roll_link</child>
        <parent>l_sho_pitch_link</parent>
        <axis>
          <xyz>-1 0 0</xyz>
          <limit>
            <lower>-2.61799</lower>
            <upper>2.61799</upper>
            <effort>2.8</effort>
            <velocity>5.64867</velocity>
          </limit>
          <dynamics>
            <spring_reference>0</spring_reference>
            <spring_stiffness>0</spring_stiffness>
          </dynamics>
          <use_parent_model_frame>1</use_parent_model_frame>
        </axis>
      </joint>
      <link name='l_el_link'>
        <pose frame=''>0.021 0.09075 0.3207 0 -0 0</pose>
        <inertial>
          <pose frame=''>-0.01349 0.006666 -0.045838 0 -0 0</pose>
          <mass>0.0592885</mass>
          <inertia>
            <ixx>0.0868553</ixx>
            <ixy>0.00530203</ixy>
            <ixz>0.000436361</ixz>
            <iyy>0.0211921</iyy>
            <iyz>-0.00648559</iyz>
            <izz>0.0868455</izz>
          </inertia>
        </inertial>
        <collision name='l_el_link_collision'>
          <pose frame=''>0 0 0 0 -0 0</pose>
          <geometry>
            <mesh>
              <scale>1 1 1</scale>
              <uri>/home/haritsahm/alfarobi_ws/src/ROBOTIS-Common/alfarobi_description/mesh/l_elbow.stl</uri>
            </mesh>
          </geometry>
          <surface>
            <contact>
              <ode/>
            </contact>
            <friction>
              <ode>
                <mu>0.2</mu>
                <mu2>0.2</mu2>
              </ode>
              <torsional>
                <ode/>
              </torsional>
            </friction>
            <bounce/>
          </surface>
          <max_contacts>10</max_contacts>
        </collision>
        <visual name='l_el_link_visual'>
          <pose frame=''>0 0 0 0 -0 0</pose>
          <geometry>
            <mesh>
              <scale>1 1 1</scale>
              <uri>/home/haritsahm/alfarobi_ws/src/ROBOTIS-Common/alfarobi_description/mesh/l_elbow.stl</uri>
            </mesh>
          </geometry>
          <material>
            <script>
              <name>Gazebo/White</name>
              <uri>file://media/materials/scripts/gazebo.material</uri>
            </script>
          </material>
        </visual>
        <gravity>1</gravity>
        <velocity_decay/>
        <self_collide>0</self_collide>
        <gravity>1</gravity>
        <kinematic>0</kinematic>
      </link>
      <joint name='l_el' type='revolute'>
        <child>l_el_link</child>
        <parent>l_sho_roll_link</parent>
        <axis>
          <xyz>0 1 0</xyz>
          <limit>
            <lower>-2.61799</lower>
            <upper>2.61799</upper>
            <effort>2.8</effort>
            <velocity>5.65487</velocity>
          </limit>
          <dynamics>
            <spring_reference>0</spring_reference>
            <spring_stiffness>0</spring_stiffness>
          </dynamics>
          <use_parent_model_frame>1</use_parent_model_frame>
        </axis>
      </joint>
      <link name='r_hip_yaw_link'>
        <pose frame=''>0 -0.038525 0.2766 0 -0 0</pose>
        <inertial>
          <pose frame=''>0 0.001844 0.00048 0 -0 0</pose>
          <mass>0.0270692</mass>
          <inertia>
            <ixx>0.0150191</ixx>
            <ixy>0</ixy>
            <ixz>0</ixz>
            <iyy>0.0113288</iyy>
            <iyz>-0.0007335</iyz>
            <izz>0.00618255</izz>
          </inertia>
        </inertial>
        <collision name='r_hip_yaw_link_collision'>
          <pose frame=''>0 0 0 0 -0 0</pose>
          <geometry>
            <mesh>
              <scale>1 1 1</scale>
              <uri>/home/haritsahm/alfarobi_ws/src/ROBOTIS-Common/alfarobi_description/mesh/hip_yaw.stl</uri>
            </mesh>
          </geometry>
          <surface>
            <contact>
              <ode/>
            </contact>
            <friction>
              <ode>
                <mu>0.2</mu>
                <mu2>0.2</mu2>
              </ode>
              <torsional>
                <ode/>
              </torsional>
            </friction>
            <bounce/>
          </surface>
          <max_contacts>10</max_contacts>
        </collision>
        <visual name='r_hip_yaw_link_visual'>
          <pose frame=''>0 0 0 0 -0 0</pose>
          <geometry>
            <mesh>
              <scale>1 1 1</scale>
              <uri>/home/haritsahm/alfarobi_ws/src/ROBOTIS-Common/alfarobi_description/mesh/hip_yaw.stl</uri>
            </mesh>
          </geometry>
          <material>
            <script>
              <name>Gazebo/Grey</name>
              <uri>file://media/materials/scripts/gazebo.material</uri>
            </script>
          </material>
        </visual>
        <gravity>1</gravity>
        <velocity_decay/>
        <self_collide>0</self_collide>
        <gravity>1</gravity>
        <kinematic>0</kinematic>
      </link>
      <joint name='r_hip_yaw' type='revolute'>
        <child>r_hip_yaw_link</child>
        <parent>base_link</parent>
        <axis>
          <xyz>0 0 -1</xyz>
          <limit>
            <lower>-2.61799</lower>
            <upper>2.61799</upper>
            <effort>2.8</effort>
            <velocity>5.65487</velocity>
          </limit>
          <dynamics>
            <spring_reference>0</spring_reference>
            <spring_stiffness>0</spring_stiffness>
          </dynamics>
          <use_parent_model_frame>1</use_parent_model_frame>
        </axis>
      </joint>
      <link name='r_hip_roll_link'>
        <pose frame=''>0 -0.038525 0.2766 0 -0 0</pose>
        <inertial>
          <pose frame=''>-0.018242 8e-05 -0.013873 0 -0 0</pose>
          <mass>0.167108</mass>
          <inertia>
            <ixx>0.122597</ixx>
            <ixy>0.000711275</ixy>
            <ixz>0.000811439</ixz>
            <iyy>0.110666</iyy>
            <iyz>-0.00716355</iyz>
            <izz>0.0418777</izz>
          </inertia>
        </inertial>
        <collision name='r_hip_roll_link_collision'>
          <pose frame=''>0 0 0 0 -0 0</pose>
          <geometry>
            <mesh>
              <scale>1 1 1</scale>
              <uri>/home/haritsahm/alfarobi_ws/src/ROBOTIS-Common/alfarobi_description/mesh/r_hip_roll.stl</uri>
            </mesh>
          </geometry>
          <surface>
            <contact>
              <ode/>
            </contact>
            <friction>
              <ode>
                <mu>0.2</mu>
                <mu2>0.2</mu2>
              </ode>
              <torsional>
                <ode/>
              </torsional>
            </friction>
            <bounce/>
          </surface>
          <max_contacts>10</max_contacts>
        </collision>
        <visual name='r_hip_roll_link_visual'>
          <pose frame=''>0 0 0 0 -0 0</pose>
          <geometry>
            <mesh>
              <scale>1 1 1</scale>
              <uri>/home/haritsahm/alfarobi_ws/src/ROBOTIS-Common/alfarobi_description/mesh/r_hip_roll.stl</uri>
            </mesh>
          </geometry>
          <material>
            <script>
              <name>Gazebo/Grey</name>
              <uri>file://media/materials/scripts/gazebo.material</uri>
            </script>
          </material>
        </visual>
        <gravity>1</gravity>
        <velocity_decay/>
        <self_collide>0</self_collide>
        <gravity>1</gravity>
        <kinematic>0</kinematic>
      </link>
      <joint name='r_hip_roll' type='revolute'>
        <child>r_hip_roll_link</child>
        <parent>r_hip_yaw_link</parent>
        <axis>
          <xyz>-1 0 0</xyz>
          <limit>
            <lower>-2.61799</lower>
            <upper>2.61799</upper>
            <effort>2.8</effort>
            <velocity>5.65487</velocity>
          </limit>
          <dynamics>
            <spring_reference>0</spring_reference>
            <spring_stiffness>0</spring_stiffness>
          </dynamics>
          <use_parent_model_frame>1</use_parent_model_frame>
        </axis>
      </joint>
      <link name='r_hip_pitch_link'>
        <pose frame=''>0 -0.038525 0.2766 0 -0 0</pose>
        <inertial>
          <pose frame=''>0.000692 -0.000323 -0.092966 0 -0 0</pose>
          <mass>0.119043</mass>
          <inertia>
            <ixx>0.0979503</ixx>
            <ixy>0.00121194</ixy>
            <ixz>-0.00021223</ixz>
            <iyy>0.0328483</iyy>
            <iyz>-0.0019474</iyz>
            <izz>0.114935</izz>
          </inertia>
        </inertial>
        <collision name='r_hip_pitch_link_collision'>
          <pose frame=''>0 0 0 0 -0 0</pose>
          <geometry>
            <mesh>
              <scale>1 1 1</scale>
              <uri>/home/haritsahm/alfarobi_ws/src/ROBOTIS-Common/alfarobi_description/mesh/r_hip_pitch.stl</uri>
            </mesh>
          </geometry>
          <surface>
            <contact>
              <ode/>
            </contact>
            <friction>
              <ode>
                <mu>0.2</mu>
                <mu2>0.2</mu2>
              </ode>
              <torsional>
                <ode/>
              </torsional>
            </friction>
            <bounce/>
          </surface>
          <max_contacts>10</max_contacts>
        </collision>
        <visual name='r_hip_pitch_link_visual'>
          <pose frame=''>0 0 0 0 -0 0</pose>
          <geometry>
            <mesh>
              <scale>1 1 1</scale>
              <uri>/home/haritsahm/alfarobi_ws/src/ROBOTIS-Common/alfarobi_description/mesh/r_hip_pitch.stl</uri>
            </mesh>
          </geometry>
          <material>
            <script>
              <name>Gazebo/White</name>
              <uri>file://media/materials/scripts/gazebo.material</uri>
            </script>
          </material>
        </visual>
        <gravity>1</gravity>
        <velocity_decay/>
        <self_collide>0</self_collide>
        <gravity>1</gravity>
        <kinematic>0</kinematic>
      </link>
      <joint name='r_hip_pitch' type='revolute'>
        <child>r_hip_pitch_link</child>
        <parent>r_hip_roll_link</parent>
        <axis>
          <xyz>0 1 0</xyz>
          <limit>
            <lower>-2.61799</lower>
            <upper>2.61799</upper>
            <effort>2.8</effort>
            <velocity>5.65487</velocity>
          </limit>
          <dynamics>
            <spring_reference>0</spring_reference>
            <spring_stiffness>0</spring_stiffness>
          </dynamics>
          <use_parent_model_frame>1</use_parent_model_frame>
        </axis>
      </joint>
      <link name='r_knee_link'>
        <pose frame=''>0 -0.038525 0.1598 0 -0 0</pose>
        <inertial>
          <pose frame=''>0.006548 -0.000592 -0.053955 0 -0 0</pose>
          <mass>0.0703098</mass>
          <inertia>
            <ixx>0.0933696</ixx>
            <ixy>-0.000935674</ixy>
            <ixz>-0.000239921</ixz>
            <iyy>0.0462955</iyy>
            <iyz>-0.0128585</iyz>
            <izz>0.113515</izz>
          </inertia>
        </inertial>
        <collision name='r_knee_link_collision'>
          <pose frame=''>0 0 0 0 -0 0</pose>
          <geometry>
            <mesh>
              <scale>1 1 1</scale>
              <uri>/home/haritsahm/alfarobi_ws/src/ROBOTIS-Common/alfarobi_description/mesh/lower_leg.stl</uri>
            </mesh>
          </geometry>
          <surface>
            <contact>
              <ode/>
            </contact>
            <friction>
              <ode>
                <mu>0.2</mu>
                <mu2>0.2</mu2>
              </ode>
              <torsional>
                <ode/>
              </torsional>
            </friction>
            <bounce/>
          </surface>
          <max_contacts>10</max_contacts>
        </collision>
        <visual name='r_knee_link_visual'>
          <pose frame=''>0 0 0 0 -0 0</pose>
          <geometry>
            <mesh>
              <scale>1 1 1</scale>
              <uri>/home/haritsahm/alfarobi_ws/src/ROBOTIS-Common/alfarobi_description/mesh/lower_leg.stl</uri>
            </mesh>
          </geometry>
          <material>
            <script>
              <name>Gazebo/White</name>
              <uri>file://media/materials/scripts/gazebo.material</uri>
            </script>
          </material>
        </visual>
        <gravity>1</gravity>
        <velocity_decay/>
        <self_collide>0</self_collide>
        <gravity>1</gravity>
        <kinematic>0</kinematic>
      </link>
      <joint name='r_knee' type='revolute'>
        <child>r_knee_link</child>
        <parent>r_hip_pitch_link</parent>
        <axis>
          <xyz>0 1 0</xyz>
          <limit>
            <lower>-2.61799</lower>
            <upper>2.61799</upper>
            <effort>2.8</effort>
            <velocity>5.65487</velocity>
          </limit>
          <dynamics>
            <spring_reference>0</spring_reference>
            <spring_stiffness>0</spring_stiffness>
          </dynamics>
          <use_parent_model_frame>1</use_parent_model_frame>
        </axis>
      </joint>
      <link name='r_ank_pitch_link'>
        <pose frame=''>0 -0.038525 0.043 0 -0 0</pose>
        <inertial>
          <pose frame=''>-0.018536 -0.000214 0.013873 0 -0 0</pose>
          <mass>0.167108</mass>
          <inertia>
            <ixx>0.120792</ixx>
            <ixy>-0.000797811</ixy>
            <ixz>-0.000393222</ixz>
            <iyy>0.108855</iyy>
            <iyz>0.00707701</iyz>
            <izz>0.0418711</izz>
          </inertia>
        </inertial>
        <collision name='r_ank_pitch_link_collision'>
          <pose frame=''>0 0 0 0 -0 0</pose>
          <geometry>
            <mesh>
              <scale>1 1 1</scale>
              <uri>/home/haritsahm/alfarobi_ws/src/ROBOTIS-Common/alfarobi_description/mesh/r_ank_pitch.stl</uri>
            </mesh>
          </geometry>
          <surface>
            <contact>
              <ode/>
            </contact>
            <friction>
              <ode>
                <mu>0.2</mu>
                <mu2>0.2</mu2>
              </ode>
              <torsional>
                <ode/>
              </torsional>
            </friction>
            <bounce/>
          </surface>
          <max_contacts>10</max_contacts>
        </collision>
        <visual name='r_ank_pitch_link_visual'>
          <pose frame=''>0 0 0 0 -0 0</pose>
          <geometry>
            <mesh>
              <scale>1 1 1</scale>
              <uri>/home/haritsahm/alfarobi_ws/src/ROBOTIS-Common/alfarobi_description/mesh/r_ank_pitch.stl</uri>
            </mesh>
          </geometry>
          <material>
            <script>
              <name>Gazebo/Grey</name>
              <uri>file://media/materials/scripts/gazebo.material</uri>
            </script>
          </material>
        </visual>
        <gravity>1</gravity>
        <velocity_decay/>
        <self_collide>0</self_collide>
        <gravity>1</gravity>
        <kinematic>0</kinematic>
      </link>
      <joint name='r_ank_pitch' type='revolute'>
        <child>r_ank_pitch_link</child>
        <parent>r_knee_link</parent>
        <axis>
          <xyz>0 -1 0</xyz>
          <limit>
            <lower>-2.61799</lower>
            <upper>2.61799</upper>
            <effort>2.8</effort>
            <velocity>5.65487</velocity>
          </limit>
          <dynamics>
            <spring_reference>0</spring_reference>
            <spring_stiffness>0</spring_stiffness>
          </dynamics>
          <use_parent_model_frame>1</use_parent_model_frame>
        </axis>
      </joint>
      <link name='r_ank_roll_link'>
        <pose frame=''>0 -0.038525 0.043 0 -0 0</pose>
        <inertial>
          <pose frame=''>-0.000503 -0.009506 -0.025995 0 -0 0</pose>
          <mass>0.0794462</mass>
          <inertia>
            <ixx>0.0683256</ixx>
            <ixy>0.00253305</ixy>
            <ixz>0.000218696</ixz>
            <iyy>0.0878905</iyy>
            <iyz>0.000976205</iyz>
            <izz>0.0358408</izz>
          </inertia>
        </inertial>
        <collision name='r_ank_roll_link_collision'>
          <pose frame=''>0 0 0 0 -0 0</pose>
          <geometry>
            <mesh>
              <scale>1 1 1</scale>
              <uri>/home/haritsahm/alfarobi_ws/src/ROBOTIS-Common/alfarobi_description/mesh/leg_ank_roll_r.stl</uri>
            </mesh>
          </geometry>
          <surface>
            <contact>
              <ode>
                <kp>100000</kp>
                <kd>100</kd>
                <max_vel>1</max_vel>
                <min_depth>0.001</min_depth>
              </ode>
            </contact>
            <friction>
              <ode>
                <mu>1.5</mu>
                <mu2>1.5</mu2>
                <fdir1>1 0 0</fdir1>
              </ode>
              <torsional>
                <ode/>
              </torsional>
            </friction>
            <bounce/>
          </surface>
          <max_contacts>10</max_contacts>
        </collision>
        <visual name='r_ank_roll_link_visual'>
          <pose frame=''>0 0 0 0 -0 0</pose>
          <geometry>
            <mesh>
              <scale>1 1 1</scale>
              <uri>/home/haritsahm/alfarobi_ws/src/ROBOTIS-Common/alfarobi_description/mesh/leg_ank_roll_r.stl</uri>
            </mesh>
          </geometry>
          <material>
            <script>
              <name>Gazebo/White</name>
              <uri>file://media/materials/scripts/gazebo.material</uri>
            </script>
          </material>
        </visual>
        <gravity>1</gravity>
        <velocity_decay/>
        <self_collide>0</self_collide>
        <gravity>1</gravity>
        <kinematic>0</kinematic>
      </link>
      <joint name='r_ank_roll' type='revolute'>
        <child>r_ank_roll_link</child>
        <parent>r_ank_pitch_link</parent>
        <axis>
          <xyz>1 0 0</xyz>
          <limit>
            <lower>-2.61799</lower>
            <upper>2.61799</upper>
            <effort>2.8</effort>
            <velocity>5.65487</velocity>
          </limit>
          <dynamics>
            <spring_reference>0</spring_reference>
            <spring_stiffness>0</spring_stiffness>
          </dynamics>
          <use_parent_model_frame>1</use_parent_model_frame>
        </axis>
      </joint>
      <link name='r_sho_pitch_link'>
        <pose frame=''>0 -0.06625 0.4439 0 -0 0</pose>
        <inertial>
          <pose frame=''>0.001352 -0.010264 0.001394 0 -0 0</pose>
          <mass>0.025913</mass>
          <inertia>
            <ixx>0.00977582</ixx>
            <ixy>0.00169118</ixy>
            <ixz>-0.000451743</ixz>
            <iyy>0.0105111</iyy>
            <iyz>0.00033407</iyz>
            <izz>0.0054768</izz>
          </inertia>
        </inertial>
        <collision name='r_sho_pitch_link_collision'>
          <pose frame=''>0 0 0 0 -0 0</pose>
          <geometry>
            <mesh>
              <scale>1 1 1</scale>
              <uri>/home/haritsahm/alfarobi_ws/src/ROBOTIS-Common/alfarobi_description/mesh/r_shoulder_pitch.stl</uri>
            </mesh>
          </geometry>
          <surface>
            <contact>
              <ode/>
            </contact>
            <friction>
              <ode>
                <mu>0.2</mu>
                <mu2>0.2</mu2>
              </ode>
              <torsional>
                <ode/>
              </torsional>
            </friction>
            <bounce/>
          </surface>
          <max_contacts>10</max_contacts>
        </collision>
        <visual name='r_sho_pitch_link_visual'>
          <pose frame=''>0 0 0 0 -0 0</pose>
          <geometry>
            <mesh>
              <scale>1 1 1</scale>
              <uri>/home/haritsahm/alfarobi_ws/src/ROBOTIS-Common/alfarobi_description/mesh/r_shoulder_pitch.stl</uri>
            </mesh>
          </geometry>
          <material>
            <script>
              <name>Gazebo/Grey</name>
              <uri>file://media/materials/scripts/gazebo.material</uri>
            </script>
          </material>
        </visual>
        <gravity>1</gravity>
        <velocity_decay/>
        <self_collide>0</self_collide>
        <gravity>1</gravity>
        <kinematic>0</kinematic>
      </link>
      <joint name='r_sho_pitch' type='revolute'>
        <child>r_sho_pitch_link</child>
        <parent>base_link</parent>
        <axis>
          <xyz>0 -1 0</xyz>
          <limit>
            <lower>-2.61799</lower>
            <upper>2.61799</upper>
            <effort>2.8</effort>
            <velocity>5.65487</velocity>
          </limit>
          <dynamics>
            <spring_reference>0</spring_reference>
            <spring_stiffness>0</spring_stiffness>
          </dynamics>
          <use_parent_model_frame>1</use_parent_model_frame>
        </axis>
      </joint>
      <link name='r_sho_roll_link'>
        <pose frame=''>0 -0.09075 0.4279 0 -0 0</pose>
        <inertial>
          <pose frame=''>0.000734 0.00066 -0.046239 0 -0 0</pose>
          <mass>0.168377</mass>
          <inertia>
            <ixx>0.122028</ixx>
            <ixy>-0.00208126</ixy>
            <ixz>-0.000881434</ixz>
            <iyy>0.0380884</iyy>
            <iyz>0.00182514</iyz>
            <izz>0.113408</izz>
          </inertia>
        </inertial>
        <collision name='r_sho_roll_link_collision'>
          <pose frame=''>0 0 0 0 -0 0</pose>
          <geometry>
            <mesh>
              <scale>1 1 1</scale>
              <uri>/home/haritsahm/alfarobi_ws/src/ROBOTIS-Common/alfarobi_description/mesh/r_shoulder_roll.stl</uri>
            </mesh>
          </geometry>
          <surface>
            <contact>
              <ode/>
            </contact>
            <friction>
              <ode>
                <mu>0.2</mu>
                <mu2>0.2</mu2>
              </ode>
              <torsional>
                <ode/>
              </torsional>
            </friction>
            <bounce/>
          </surface>
          <max_contacts>10</max_contacts>
        </collision>
        <visual name='r_sho_roll_link_visual'>
          <pose frame=''>0 0 0 0 -0 0</pose>
          <geometry>
            <mesh>
              <scale>1 1 1</scale>
              <uri>/home/haritsahm/alfarobi_ws/src/ROBOTIS-Common/alfarobi_description/mesh/r_shoulder_roll.stl</uri>
            </mesh>
          </geometry>
          <material>
            <script>
              <name>Gazebo/White</name>
              <uri>file://media/materials/scripts/gazebo.material</uri>
            </script>
          </material>
        </visual>
        <gravity>1</gravity>
        <velocity_decay/>
        <self_collide>0</self_collide>
        <gravity>1</gravity>
        <kinematic>0</kinematic>
      </link>
      <joint name='r_sho_roll' type='revolute'>
        <child>r_sho_roll_link</child>
        <parent>r_sho_pitch_link</parent>
        <axis>
          <xyz>1 0 0</xyz>
          <limit>
            <lower>-2.61799</lower>
            <upper>2.61799</upper>
            <effort>2.8</effort>
            <velocity>5.64867</velocity>
          </limit>
          <dynamics>
            <spring_reference>0</spring_reference>
            <spring_stiffness>0</spring_stiffness>
          </dynamics>
          <use_parent_model_frame>1</use_parent_model_frame>
        </axis>
      </joint>
      <link name='r_el_link'>
        <pose frame=''>0.021 -0.09075 0.3207 0 -0 0</pose>
        <inertial>
          <pose frame=''>-0.01349 -0.006666 -0.045838 0 -0 0</pose>
          <mass>0.0592885</mass>
          <inertia>
            <ixx>0.0868553</ixx>
            <ixy>0.00530203</ixy>
            <ixz>0.000436361</ixz>
            <iyy>0.0211921</iyy>
            <iyz>-0.00648559</iyz>
            <izz>0.0868455</izz>
          </inertia>
        </inertial>
        <collision name='r_el_link_collision'>
          <pose frame=''>0 0 0 0 -0 0</pose>
          <geometry>
            <mesh>
              <scale>1 1 1</scale>
              <uri>/home/haritsahm/alfarobi_ws/src/ROBOTIS-Common/alfarobi_description/mesh/r_elbow.stl</uri>
            </mesh>
          </geometry>
          <surface>
            <contact>
              <ode/>
            </contact>
            <friction>
              <ode>
                <mu>0.2</mu>
                <mu2>0.2</mu2>
              </ode>
              <torsional>
                <ode/>
              </torsional>
            </friction>
            <bounce/>
          </surface>
          <max_contacts>10</max_contacts>
        </collision>
        <visual name='r_el_link_visual'>
          <pose frame=''>0 0 0 0 -0 0</pose>
          <geometry>
            <mesh>
              <scale>1 1 1</scale>
              <uri>/home/haritsahm/alfarobi_ws/src/ROBOTIS-Common/alfarobi_description/mesh/r_elbow.stl</uri>
            </mesh>
          </geometry>
          <material>
            <script>
              <name>Gazebo/White</name>
              <uri>file://media/materials/scripts/gazebo.material</uri>
            </script>
          </material>
        </visual>
        <gravity>1</gravity>
        <velocity_decay/>
        <self_collide>0</self_collide>
        <gravity>1</gravity>
        <kinematic>0</kinematic>
      </link>
      <joint name='r_el' type='revolute'>
        <child>r_el_link</child>
        <parent>r_sho_roll_link</parent>
        <axis>
          <xyz>0 -1 0</xyz>
          <limit>
            <lower>-2.61799</lower>
            <upper>2.61799</upper>
            <effort>2.8</effort>
            <velocity>5.65487</velocity>
          </limit>
          <dynamics>
            <spring_reference>0</spring_reference>
            <spring_stiffness>0</spring_stiffness>
          </dynamics>
          <use_parent_model_frame>1</use_parent_model_frame>
        </axis>
      </joint>
      <static>0</static>
      <plugin name='gazebo_ros_control' filename='libgazebo_ros_control.so'>
        <robotNamespace>/alfarobi</robotNamespace>
        <robotSimType>gazebo_ros_control/DefaultRobotHWSim</robotSimType>
      </plugin>
      <pose frame=''>-1 0 0 0 -0 0</pose>
    </model>
  </world>
</sdf>
